Workbook

Sheet Overview
A1: EXPERIMENT / SESSION OVERVIEW | P1: CONTROLS | R1: RESOLVED MACHINE FIELDS | AY1: Active highlight | AZ1: TRUE
A2: Exp | B2: Date | C2: Time | D2: Name | E2: Arrangement | F2: annotationSet | G2: Replicate label | H2: Description text | I2: Ext | J2: Include | K2: Images | L2: Reg start | M2: Reg end | N2: Status | O2: ID | P2: VBA controls | R2: Exp* | S2: Date* | T2: Name* | U2: Arrangement* | V2: annotationSet* | W2: Description text* | X2: Ext* | Y2: sessionUID* | Z2: Replicate label* | AY2: Legend visible | AZ2: FALSE
A3: 1 | B3: 14.08.26 | C3: 24h | E3: Arrangement 1 | F3: annotationSet 1 | H3: growth | I3: .jpg | J3: TRUE | K3: =IF(B3="","",COUNTIF(Arrangements!$M$3:$M$92,U3)) -> 24 | L3: =IF(OR(B3="",N3<>"OK"),"",1) -> 1 | M3: =IF(L3="","",L3+K3-1) -> 24 | N3: =IF(B3="","",IF(J3=FALSE,"Excluded",IF(R3="","Missing Exp",IF(NOT(IFERROR(TEXT(DATE(2000+VALUE(RIGHT(B3,2)),VALUE(MID(B3,4,2)),VALUE(LEFT(B3,2))),"dd.mm.yy")=B3,FALSE)),"Invalid date - use dd.mm.yy",IF(U3="","Missing Arrangement",IF(COUNTIF(Arrangements!$M$3:$M$92,U3)=0,"Unknown Arrangement",IF(SUMPRODUCT((Arrangements!$M$3:$M$92=U3)*(Arrangements!$P$3:$P$92<>"OK"))>0,"Arrangement errors",IF(AND(V3<>"",COUNTIF(Annotations!$B$3:$B$46,V3)=0),"Unknown annotationSet",IF(AND(V3<>"",COUNTIFS(Annotations!$B$3:$B$46,V3,Annotations!$F$3:$F$46,"<>OK")>0),"annotationSet errors",IF(K3=0,"No images",IF(COUNTIF($Y$3:$Y$62,Y3)>1,"Duplicate session - change Name or Time",IF(AND(A3<>"",COUNTIF($A$3:$A$62,A3)>1),"Duplicate Exp start","OK")))))))))))) -> OK | O3: =IF(B3="","",B3&IF(T3<>"","_"&T3,"")&IF(C3<>"","_"&C3,"")) -> 14.08.26_24h | P3: installed separately | R3: =IF(B3="","",IFERROR(LOOKUP(2,1/($A$3:A3<>""),$A$3:A3),"")) -> 1 | S3: =IF(B3="","",IF(IFERROR(TEXT(DATE(2000+VALUE(RIGHT(B3,2)),VALUE(MID(B3,4,2)),VALUE(LEFT(B3,2))),"dd.mm.yy")=B3,FALSE),DATE(2000+VALUE(RIGHT(B3,2)),VALUE(MID(B3,4,2)),VALUE(LEFT(B3,2))),"")) -> 46248 | T3: =IF(B3="","",IFERROR(LOOKUP(2,1/(($R$3:R3=R3)*($D$3:D3<>"")),$D$3:D3),"")) | U3: =IF(B3="","",IFERROR(LOOKUP(2,1/(($R$3:R3=R3)*($E$3:E3<>"")),$E$3:E3),"")) -> Arrangement 1 | V3: =IF(B3="","",IFERROR(LOOKUP(2,1/(($R$3:R3=R3)*($F$3:F3<>"")),$F$3:F3),"")) -> annotationSet 1 | W3: =IF(B3="","",IF(IFERROR(LOOKUP(2,1/(($R$3:R3=R3)*($H$3:H3<>"")),$H$3:H3),"growth")="[none]","",IFERROR(LOOKUP(2,1/(($R$3:R3=R3)*($H$3:H3<>"")),$H$3:H3),"growth"))) -> growth | X3: =IF(B3="","",IFERROR(LOOKUP(2,1/(($R$3:R3=R3)*($I$3:I3<>"")),$I$3:I3),".jpg")) -> .jpg | Y3: =IF(OR(B3="",R3="",S3=""),"","E"&R3&"_"&B3&IF(T3<>"","_"&T3,"")&IF(C3<>"","_"&C3,"")) -> E1_14.08.26_24h | Z3: =IF(B3="","",IF(IFERROR(LOOKUP(2,1/(($R$3:R3=R3)*($G$3:G3<>"")),$G$3:G3),"")="[none]","",IFERROR(LOOKUP(2,1/(($R$3:R3=R3)*($G$3:G3<>"")),$G$3:G3),""))) | AY3: VBA live | AZ3: FALSE
B4: 15.08.26 | C4: 48h | J4: TRUE | K4: =IF(B4="","",COUNTIF(Arrangements!$M$3:$M$92,U4)) -> 24 | L4: =IF(OR(B4="",N4<>"OK"),"",1+SUMIFS($K$3:K3,$N$3:N3,"OK")) -> 25 | M4: =IF(L4="","",L4+K4-1) -> 48 | N4: =IF(B4="","",IF(J4=FALSE,"Excluded",IF(R4="","Missing Exp",IF(NOT(IFERROR(TEXT(DATE(2000+VALUE(RIGHT(B4,2)),VALUE(MID(B4,4,2)),VALUE(LEFT(B4,2))),"dd.mm.yy")=B4,FALSE)),"Invalid date - use dd.mm.yy",IF(U4="","Missing Arrangement",IF(COUNTIF(Arrangements!$M$3:$M$92,U4)=0,"Unknown Arrangement",IF(SUMPRODUCT((Arrangements!$M$3:$M$92=U4)*(Arrangements!$P$3:$P$92<>"OK"))>0,"Arrangement errors",IF(AND(V4<>"",COUNTIF(Annotations!$B$3:$B$46,V4)=0),"Unknown annotationSet",IF(AND(V4<>"",COUNTIFS(Annotations!$B$3:$B$46,V4,Annotations!$F$3:$F$46,"<>OK")>0),"annotationSet errors",IF(K4=0,"No images",IF(COUNTIF($Y$3:$Y$62,Y4)>1,"Duplicate session - change Name or Time",IF(AND(A4<>"",COUNTIF($A$3:$A$62,A4)>1),"Duplicate Exp start","OK")))))))))))) -> OK | O4: =IF(B4="","",B4&IF(T4<>"","_"&T4,"")&IF(C4<>"","_"&C4,"")) -> 15.08.26_48h | P4: LIVE / PAUSED | R4: =IF(B4="","",IFERROR(LOOKUP(2,1/($A$3:A4<>""),$A$3:A4),"")) -> 1 | S4: =IF(B4="","",IF(IFERROR(TEXT(DATE(2000+VALUE(RIGHT(B4,2)),VALUE(MID(B4,4,2)),VALUE(LEFT(B4,2))),"dd.mm.yy")=B4,FALSE),DATE(2000+VALUE(RIGHT(B4,2)),VALUE(MID(B4,4,2)),VALUE(LEFT(B4,2))),"")) -> 46249 | T4: =IF(B4="","",IFERROR(LOOKUP(2,1/(($R$3:R4=R4)*($D$3:D4<>"")),$D$3:D4),"")) | U4: =IF(B4="","",IFERROR(LOOKUP(2,1/(($R$3:R4=R4)*($E$3:E4<>"")),$E$3:E4),"")) -> Arrangement 1 | V4: =IF(B4="","",IFERROR(LOOKUP(2,1/(($R$3:R4=R4)*($F$3:F4<>"")),$F$3:F4),"")) -> annotationSet 1 | W4: =IF(B4="","",IF(IFERROR(LOOKUP(2,1/(($R$3:R4=R4)*($H$3:H4<>"")),$H$3:H4),"growth")="[none]","",IFERROR(LOOKUP(2,1/(($R$3:R4=R4)*($H$3:H4<>"")),$H$3:H4),"growth"))) -> growth | X4: =IF(B4="","",IFERROR(LOOKUP(2,1/(($R$3:R4=R4)*($I$3:I4<>"")),$I$3:I4),".jpg")) -> .jpg | Y4: =IF(OR(B4="",R4="",S4=""),"","E"&R4&"_"&B4&IF(T4<>"","_"&T4,"")&IF(C4<>"","_"&C4,"")) -> E1_15.08.26_48h | Z4: =IF(B4="","",IF(IFERROR(LOOKUP(2,1/(($R$3:R4=R4)*($G$3:G4<>"")),$G$3:G4),"")="[none]","",IFERROR(LOOKUP(2,1/(($R$3:R4=R4)*($G$3:G4<>"")),$G$3:G4),""))) | AY4: Sync pending | AZ4: FALSE
A5: 2 | B5: 16.08.26 | C5: 24h | E5: Arrangement 2 | F5: annotationSet 2 | H5: [none] | I5: .jpg | J5: TRUE | K5: =IF(B5="","",COUNTIF(Arrangements!$M$3:$M$92,U5)) -> 25 | L5: =IF(OR(B5="",N5<>"OK"),"",1+SUMIFS($K$3:K4,$N$3:N4,"OK")) -> 49 | M5: =IF(L5="","",L5+K5-1) -> 73 | N5: =IF(B5="","",IF(J5=FALSE,"Excluded",IF(R5="","Missing Exp",IF(NOT(IFERROR(TEXT(DATE(2000+VALUE(RIGHT(B5,2)),VALUE(MID(B5,4,2)),VALUE(LEFT(B5,2))),"dd.mm.yy")=B5,FALSE)),"Invalid date - use dd.mm.yy",IF(U5="","Missing Arrangement",IF(COUNTIF(Arrangements!$M$3:$M$92,U5)=0,"Unknown Arrangement",IF(SUMPRODUCT((Arrangements!$M$3:$M$92=U5)*(Arrangements!$P$3:$P$92<>"OK"))>0,"Arrangement errors",IF(AND(V5<>"",COUNTIF(Annotations!$B$3:$B$46,V5)=0),"Unknown annotationSet",IF(AND(V5<>"",COUNTIFS(Annotations!$B$3:$B$46,V5,Annotations!$F$3:$F$46,"<>OK")>0),"annotationSet errors",IF(K5=0,"No images",IF(COUNTIF($Y$3:$Y$62,Y5)>1,"Duplicate session - change Name or Time",IF(AND(A5<>"",COUNTIF($A$3:$A$62,A5)>1),"Duplicate Exp start","OK")))))))))))) -> OK | O5: =IF(B5="","",B5&IF(T5<>"","_"&T5,"")&IF(C5<>"","_"&C5,"")) -> 16.08.26_24h | P5: Sync Now | R5: =IF(B5="","",IFERROR(LOOKUP(2,1/($A$3:A5<>""),$A$3:A5),"")) -> 2 | S5: =IF(B5="","",IF(IFERROR(TEXT(DATE(2000+VALUE(RIGHT(B5,2)),VALUE(MID(B5,4,2)),VALUE(LEFT(B5,2))),"dd.mm.yy")=B5,FALSE),DATE(2000+VALUE(RIGHT(B5,2)),VALUE(MID(B5,4,2)),VALUE(LEFT(B5,2))),"")) -> 46250 | T5: =IF(B5="","",IFERROR(LOOKUP(2,1/(($R$3:R5=R5)*($D$3:D5<>"")),$D$3:D5),"")) | U5: =IF(B5="","",IFERROR(LOOKUP(2,1/(($R$3:R5=R5)*($E$3:E5<>"")),$E$3:E5),"")) -> Arrangement 2 | V5: =IF(B5="","",IFERROR(LOOKUP(2,1/(($R$3:R5=R5)*($F$3:F5<>"")),$F$3:F5),"")) -> annotationSet 2 | W5: =IF(B5="","",IF(IFERROR(LOOKUP(2,1/(($R$3:R5=R5)*($H$3:H5<>"")),$H$3:H5),"growth")="[none]","",IFERROR(LOOKUP(2,1/(($R$3:R5=R5)*($H$3:H5<>"")),$H$3:H5),"growth"))) | X5: =IF(B5="","",IFERROR(LOOKUP(2,1/(($R$3:R5=R5)*($I$3:I5<>"")),$I$3:I5),".jpg")) -> .jpg | Y5: =IF(OR(B5="",R5="",S5=""),"","E"&R5&"_"&B5&IF(T5<>"","_"&T5,"")&IF(C5<>"","_"&C5,"")) -> E2_16.08.26_24h | Z5: =IF(B5="","",IF(IFERROR(LOOKUP(2,1/(($R$3:R5=R5)*($G$3:G5<>"")),$G$3:G5),"")="[none]","",IFERROR(LOOKUP(2,1/(($R$3:R5=R5)*($G$3:G5<>"")),$G$3:G5),""))) | AY5: Capacity row | AZ5: 62
B6: 17.08.26 | C6: 48h | J6: TRUE | K6: =IF(B6="","",COUNTIF(Arrangements!$M$3:$M$92,U6)) -> 25 | L6: =IF(OR(B6="",N6<>"OK"),"",1+SUMIFS($K$3:K5,$N$3:N5,"OK")) -> 74 | M6: =IF(L6="","",L6+K6-1) -> 98 | N6: =IF(B6="","",IF(J6=FALSE,"Excluded",IF(R6="","Missing Exp",IF(NOT(IFERROR(TEXT(DATE(2000+VALUE(RIGHT(B6,2)),VALUE(MID(B6,4,2)),VALUE(LEFT(B6,2))),"dd.mm.yy")=B6,FALSE)),"Invalid date - use dd.mm.yy",IF(U6="","Missing Arrangement",IF(COUNTIF(Arrangements!$M$3:$M$92,U6)=0,"Unknown Arrangement",IF(SUMPRODUCT((Arrangements!$M$3:$M$92=U6)*(Arrangements!$P$3:$P$92<>"OK"))>0,"Arrangement errors",IF(AND(V6<>"",COUNTIF(Annotations!$B$3:$B$46,V6)=0),"Unknown annotationSet",IF(AND(V6<>"",COUNTIFS(Annotations!$B$3:$B$46,V6,Annotations!$F$3:$F$46,"<>OK")>0),"annotationSet errors",IF(K6=0,"No images",IF(COUNTIF($Y$3:$Y$62,Y6)>1,"Duplicate session - change Name or Time",IF(AND(A6<>"",COUNTIF($A$3:$A$62,A6)>1),"Duplicate Exp start","OK")))))))))))) -> OK | O6: =IF(B6="","",B6&IF(T6<>"","_"&T6,"")&IF(C6<>"","_"&C6,"")) -> 17.08.26_48h | P6: Legend (bottom) | R6: =IF(B6="","",IFERROR(LOOKUP(2,1/($A$3:A6<>""),$A$3:A6),"")) -> 2 | S6: =IF(B6="","",IF(IFERROR(TEXT(DATE(2000+VALUE(RIGHT(B6,2)),VALUE(MID(B6,4,2)),VALUE(LEFT(B6,2))),"dd.mm.yy")=B6,FALSE),DATE(2000+VALUE(RIGHT(B6,2)),VALUE(MID(B6,4,2)),VALUE(LEFT(B6,2))),"")) -> 46251 | T6: =IF(B6="","",IFERROR(LOOKUP(2,1/(($R$3:R6=R6)*($D$3:D6<>"")),$D$3:D6),"")) | U6: =IF(B6="","",IFERROR(LOOKUP(2,1/(($R$3:R6=R6)*($E$3:E6<>"")),$E$3:E6),"")) -> Arrangement 2 | V6: =IF(B6="","",IFERROR(LOOKUP(2,1/(($R$3:R6=R6)*($F$3:F6<>"")),$F$3:F6),"")) -> annotationSet 2 | W6: =IF(B6="","",IF(IFERROR(LOOKUP(2,1/(($R$3:R6=R6)*($H$3:H6<>"")),$H$3:H6),"growth")="[none]","",IFERROR(LOOKUP(2,1/(($R$3:R6=R6)*($H$3:H6<>"")),$H$3:H6),"growth"))) | X6: =IF(B6="","",IFERROR(LOOKUP(2,1/(($R$3:R6=R6)*($I$3:I6<>"")),$I$3:I6),".jpg")) -> .jpg | Y6: =IF(OR(B6="",R6="",S6=""),"","E"&R6&"_"&B6&IF(T6<>"","_"&T6,"")&IF(C6<>"","_"&C6,"")) -> E2_17.08.26_48h | Z6: =IF(B6="","",IF(IFERROR(LOOKUP(2,1/(($R$3:R6=R6)*($G$3:G6<>"")),$G$3:G6),"")="[none]","",IFERROR(LOOKUP(2,1/(($R$3:R6=R6)*($G$3:G6<>"")),$G$3:G6),"")))
K7: =IF(B7="","",COUNTIF(Arrangements!$M$3:$M$92,U7)) | L7: =IF(OR(B7="",N7<>"OK"),"",1+SUMIFS($K$3:K6,$N$3:N6,"OK")) | M7: =IF(L7="","",L7+K7-1) | N7: =IF(B7="","",IF(J7=FALSE,"Excluded",IF(R7="","Missing Exp",IF(NOT(IFERROR(TEXT(DATE(2000+VALUE(RIGHT(B7,2)),VALUE(MID(B7,4,2)),VALUE(LEFT(B7,2))),"dd.mm.yy")=B7,FALSE)),"Invalid date - use dd.mm.yy",IF(U7="","Missing Arrangement",IF(COUNTIF(Arrangements!$M$3:$M$92,U7)=0,"Unknown Arrangement",IF(SUMPRODUCT((Arrangements!$M$3:$M$92=U7)*(Arrangements!$P$3:$P$92<>"OK"))>0,"Arrangement errors",IF(AND(V7<>"",COUNTIF(Annotations!$B$3:$B$46,V7)=0),"Unknown annotationSet",IF(AND(V7<>"",COUNTIFS(Annotations!$B$3:$B$46,V7,Annotations!$F$3:$F$46,"<>OK")>0),"annotationSet errors",IF(K7=0,"No images",IF(COUNTIF($Y$3:$Y$62,Y7)>1,"Duplicate session - change Name or Time",IF(AND(A7<>"",COUNTIF($A$3:$A$62,A7)>1),"Duplicate Exp start","OK")))))))))))) | O7: =IF(B7="","",B7&IF(T7<>"","_"&T7,"")&IF(C7<>"","_"&C7,"")) | R7: =IF(B7="","",IFERROR(LOOKUP(2,1/($A$3:A7<>""),$A$3:A7),"")) | S7: =IF(B7="","",IF(IFERROR(TEXT(DATE(2000+VALUE(RIGHT(B7,2)),VALUE(MID(B7,4,2)),VALUE(LEFT(B7,2))),"dd.mm.yy")=B7,FALSE),DATE(2000+VALUE(RIGHT(B7,2)),VALUE(MID(B7,4,2)),VALUE(LEFT(B7,2))),"")) | T7: =IF(B7="","",IFERROR(LOOKUP(2,1/(($R$3:R7=R7)*($D$3:D7<>"")),$D$3:D7),"")) | U7: =IF(B7="","",IFERROR(LOOKUP(2,1/(($R$3:R7=R7)*($E$3:E7<>"")),$E$3:E7),"")) | V7: =IF(B7="","",IFERROR(LOOKUP(2,1/(($R$3:R7=R7)*($F$3:F7<>"")),$F$3:F7),"")) | W7: =IF(B7="","",IF(IFERROR(LOOKUP(2,1/(($R$3:R7=R7)*($H$3:H7<>"")),$H$3:H7),"growth")="[none]","",IFERROR(LOOKUP(2,1/(($R$3:R7=R7)*($H$3:H7<>"")),$H$3:H7),"growth"))) | X7: =IF(B7="","",IFERROR(LOOKUP(2,1/(($R$3:R7=R7)*($I$3:I7<>"")),$I$3:I7),".jpg")) | Y7: =IF(OR(B7="",R7="",S7=""),"","E"&R7&"_"&B7&IF(T7<>"","_"&T7,"")&IF(C7<>"","_"&C7,"")) | Z7: =IF(B7="","",IF(IFERROR(LOOKUP(2,1/(($R$3:R7=R7)*($G$3:G7<>"")),$G$3:G7),"")="[none]","",IFERROR(LOOKUP(2,1/(($R$3:R7=R7)*($G$3:G7<>"")),$G$3:G7),"")))
K8: =IF(B8="","",COUNTIF(Arrangements!$M$3:$M$92,U8)) | L8: =IF(OR(B8="",N8<>"OK"),"",1+SUMIFS($K$3:K7,$N$3:N7,"OK")) | M8: =IF(L8="","",L8+K8-1) | N8: =IF(B8="","",IF(J8=FALSE,"Excluded",IF(R8="","Missing Exp",IF(NOT(IFERROR(TEXT(DATE(2000+VALUE(RIGHT(B8,2)),VALUE(MID(B8,4,2)),VALUE(LEFT(B8,2))),"dd.mm.yy")=B8,FALSE)),"Invalid date - use dd.mm.yy",IF(U8="","Missing Arrangement",IF(COUNTIF(Arrangements!$M$3:$M$92,U8)=0,"Unknown Arrangement",IF(SUMPRODUCT((Arrangements!$M$3:$M$92=U8)*(Arrangements!$P$3:$P$92<>"OK"))>0,"Arrangement errors",IF(AND(V8<>"",COUNTIF(Annotations!$B$3:$B$46,V8)=0),"Unknown annotationSet",IF(AND(V8<>"",COUNTIFS(Annotations!$B$3:$B$46,V8,Annotations!$F$3:$F$46,"<>OK")>0),"annotationSet errors",IF(K8=0,"No images",IF(COUNTIF($Y$3:$Y$62,Y8)>1,"Duplicate session - change Name or Time",IF(AND(A8<>"",COUNTIF($A$3:$A$62,A8)>1),"Duplicate Exp start","OK")))))))))))) | O8: =IF(B8="","",B8&IF(T8<>"","_"&T8,"")&IF(C8<>"","_"&C8,"")) | R8: =IF(B8="","",IFERROR(LOOKUP(2,1/($A$3:A8<>""),$A$3:A8),"")) | S8: =IF(B8="","",IF(IFERROR(TEXT(DATE(2000+VALUE(RIGHT(B8,2)),VALUE(MID(B8,4,2)),VALUE(LEFT(B8,2))),"dd.mm.yy")=B8,FALSE),DATE(2000+VALUE(RIGHT(B8,2)),VALUE(MID(B8,4,2)),VALUE(LEFT(B8,2))),"")) | T8: =IF(B8="","",IFERROR(LOOKUP(2,1/(($R$3:R8=R8)*($D$3:D8<>"")),$D$3:D8),"")) | U8: =IF(B8="","",IFERROR(LOOKUP(2,1/(($R$3:R8=R8)*($E$3:E8<>"")),$E$3:E8),"")) | V8: =IF(B8="","",IFERROR(LOOKUP(2,1/(($R$3:R8=R8)*($F$3:F8<>"")),$F$3:F8),"")) | W8: =IF(B8="","",IF(IFERROR(LOOKUP(2,1/(($R$3:R8=R8)*($H$3:H8<>"")),$H$3:H8),"growth")="[none]","",IFERROR(LOOKUP(2,1/(($R$3:R8=R8)*($H$3:H8<>"")),$H$3:H8),"growth"))) | X8: =IF(B8="","",IFERROR(LOOKUP(2,1/(($R$3:R8=R8)*($I$3:I8<>"")),$I$3:I8),".jpg")) | Y8: =IF(OR(B8="",R8="",S8=""),"","E"&R8&"_"&B8&IF(T8<>"","_"&T8,"")&IF(C8<>"","_"&C8,"")) | Z8: =IF(B8="","",IF(IFERROR(LOOKUP(2,1/(($R$3:R8=R8)*($G$3:G8<>"")),$G$3:G8),"")="[none]","",IFERROR(LOOKUP(2,1/(($R$3:R8=R8)*($G$3:G8<>"")),$G$3:G8),"")))
K9: =IF(B9="","",COUNTIF(Arrangements!$M$3:$M$92,U9)) | L9: =IF(OR(B9="",N9<>"OK"),"",1+SUMIFS($K$3:K8,$N$3:N8,"OK")) | M9: =IF(L9="","",L9+K9-1) | N9: =IF(B9="","",IF(J9=FALSE,"Excluded",IF(R9="","Missing Exp",IF(NOT(IFERROR(TEXT(DATE(2000+VALUE(RIGHT(B9,2)),VALUE(MID(B9,4,2)),VALUE(LEFT(B9,2))),"dd.mm.yy")=B9,FALSE)),"Invalid date - use dd.mm.yy",IF(U9="","Missing Arrangement",IF(COUNTIF(Arrangements!$M$3:$M$92,U9)=0,"Unknown Arrangement",IF(SUMPRODUCT((Arrangements!$M$3:$M$92=U9)*(Arrangements!$P$3:$P$92<>"OK"))>0,"Arrangement errors",IF(AND(V9<>"",COUNTIF(Annotations!$B$3:$B$46,V9)=0),"Unknown annotationSet",IF(AND(V9<>"",COUNTIFS(Annotations!$B$3:$B$46,V9,Annotations!$F$3:$F$46,"<>OK")>0),"annotationSet errors",IF(K9=0,"No images",IF(COUNTIF($Y$3:$Y$62,Y9)>1,"Duplicate session - change Name or Time",IF(AND(A9<>"",COUNTIF($A$3:$A$62,A9)>1),"Duplicate Exp start","OK")))))))))))) | O9: =IF(B9="","",B9&IF(T9<>"","_"&T9,"")&IF(C9<>"","_"&C9,"")) | R9: =IF(B9="","",IFERROR(LOOKUP(2,1/($A$3:A9<>""),$A$3:A9),"")) | S9: =IF(B9="","",IF(IFERROR(TEXT(DATE(2000+VALUE(RIGHT(B9,2)),VALUE(MID(B9,4,2)),VALUE(LEFT(B9,2))),"dd.mm.yy")=B9,FALSE),DATE(2000+VALUE(RIGHT(B9,2)),VALUE(MID(B9,4,2)),VALUE(LEFT(B9,2))),"")) | T9: =IF(B9="","",IFERROR(LOOKUP(2,1/(($R$3:R9=R9)*($D$3:D9<>"")),$D$3:D9),"")) | U9: =IF(B9="","",IFERROR(LOOKUP(2,1/(($R$3:R9=R9)*($E$3:E9<>"")),$E$3:E9),"")) | V9: =IF(B9="","",IFERROR(LOOKUP(2,1/(($R$3:R9=R9)*($F$3:F9<>"")),$F$3:F9),"")) | W9: =IF(B9="","",IF(IFERROR(LOOKUP(2,1/(($R$3:R9=R9)*($H$3:H9<>"")),$H$3:H9),"growth")="[none]","",IFERROR(LOOKUP(2,1/(($R$3:R9=R9)*($H$3:H9<>"")),$H$3:H9),"growth"))) | X9: =IF(B9="","",IFERROR(LOOKUP(2,1/(($R$3:R9=R9)*($I$3:I9<>"")),$I$3:I9),".jpg")) | Y9: =IF(OR(B9="",R9="",S9=""),"","E"&R9&"_"&B9&IF(T9<>"","_"&T9,"")&IF(C9<>"","_"&C9,"")) | Z9: =IF(B9="","",IF(IFERROR(LOOKUP(2,1/(($R$3:R9=R9)*($G$3:G9<>"")),$G$3:G9),"")="[none]","",IFERROR(LOOKUP(2,1/(($R$3:R9=R9)*($G$3:G9<>"")),$G$3:G9),"")))
K10: =IF(B10="","",COUNTIF(Arrangements!$M$3:$M$92,U10)) | L10: =IF(OR(B10="",N10<>"OK"),"",1+SUMIFS($K$3:K9,$N$3:N9,"OK")) | M10: =IF(L10="","",L10+K10-1) | N10: =IF(B10="","",IF(J10=FALSE,"Excluded",IF(R10="","Missing Exp",IF(NOT(IFERROR(TEXT(DATE(2000+VALUE(RIGHT(B10,2)),VALUE(MID(B10,4,2)),VALUE(LEFT(B10,2))),"dd.mm.yy")=B10,FALSE)),"Invalid date - use dd.mm.yy",IF(U10="","Missing Arrangement",IF(COUNTIF(Arrangements!$M$3:$M$92,U10)=0,"Unknown Arrangement",IF(SUMPRODUCT((Arrangements!$M$3:$M$92=U10)*(Arrangements!$P$3:$P$92<>"OK"))>0,"Arrangement errors",IF(AND(V10<>"",COUNTIF(Annotations!$B$3:$B$46,V10)=0),"Unknown annotationSet",IF(AND(V10<>"",COUNTIFS(Annotations!$B$3:$B$46,V10,Annotations!$F$3:$F$46,"<>OK")>0),"annotationSet errors",IF(K10=0,"No images",IF(COUNTIF($Y$3:$Y$62,Y10)>1,"Duplicate session - change Name or Time",IF(AND(A10<>"",COUNTIF($A$3:$A$62,A10)>1),"Duplicate Exp start","OK")))))))))))) | O10: =IF(B10="","",B10&IF(T10<>"","_"&T10,"")&IF(C10<>"","_"&C10,"")) | R10: =IF(B10="","",IFERROR(LOOKUP(2,1/($A$3:A10<>""),$A$3:A10),"")) | S10: =IF(B10="","",IF(IFERROR(TEXT(DATE(2000+VALUE(RIGHT(B10,2)),VALUE(MID(B10,4,2)),VALUE(LEFT(B10,2))),"dd.mm.yy")=B10,FALSE),DATE(2000+VALUE(RIGHT(B10,2)),VALUE(MID(B10,4,2)),VALUE(LEFT(B10,2))),"")) | T10: =IF(B10="","",IFERROR(LOOKUP(2,1/(($R$3:R10=R10)*($D$3:D10<>"")),$D$3:D10),"")) | U10: =IF(B10="","",IFERROR(LOOKUP(2,1/(($R$3:R10=R10)*($E$3:E10<>"")),$E$3:E10),"")) | V10: =IF(B10="","",IFERROR(LOOKUP(2,1/(($R$3:R10=R10)*($F$3:F10<>"")),$F$3:F10),"")) | W10: =IF(B10="","",IF(IFERROR(LOOKUP(2,1/(($R$3:R10=R10)*($H$3:H10<>"")),$H$3:H10),"growth")="[none]","",IFERROR(LOOKUP(2,1/(($R$3:R10=R10)*($H$3:H10<>"")),$H$3:H10),"growth"))) | X10: =IF(B10="","",IFERROR(LOOKUP(2,1/(($R$3:R10=R10)*($I$3:I10<>"")),$I$3:I10),".jpg")) | Y10: =IF(OR(B10="",R10="",S10=""),"","E"&R10&"_"&B10&IF(T10<>"","_"&T10,"")&IF(C10<>"","_"&C10,"")) | Z10: =IF(B10="","",IF(IFERROR(LOOKUP(2,1/(($R$3:R10=R10)*($G$3:G10<>"")),$G$3:G10),"")="[none]","",IFERROR(LOOKUP(2,1/(($R$3:R10=R10)*($G$3:G10<>"")),$G$3:G10),"")))
K11: =IF(B11="","",COUNTIF(Arrangements!$M$3:$M$92,U11)) | L11: =IF(OR(B11="",N11<>"OK"),"",1+SUMIFS($K$3:K10,$N$3:N10,"OK")) | M11: =IF(L11="","",L11+K11-1) | N11: =IF(B11="","",IF(J11=FALSE,"Excluded",IF(R11="","Missing Exp",IF(NOT(IFERROR(TEXT(DATE(2000+VALUE(RIGHT(B11,2)),VALUE(MID(B11,4,2)),VALUE(LEFT(B11,2))),"dd.mm.yy")=B11,FALSE)),"Invalid date - use dd.mm.yy",IF(U11="","Missing Arrangement",IF(COUNTIF(Arrangements!$M$3:$M$92,U11)=0,"Unknown Arrangement",IF(SUMPRODUCT((Arrangements!$M$3:$M$92=U11)*(Arrangements!$P$3:$P$92<>"OK"))>0,"Arrangement errors",IF(AND(V11<>"",COUNTIF(Annotations!$B$3:$B$46,V11)=0),"Unknown annotationSet",IF(AND(V11<>"",COUNTIFS(Annotations!$B$3:$B$46,V11,Annotations!$F$3:$F$46,"<>OK")>0),"annotationSet errors",IF(K11=0,"No images",IF(COUNTIF($Y$3:$Y$62,Y11)>1,"Duplicate session - change Name or Time",IF(AND(A11<>"",COUNTIF($A$3:$A$62,A11)>1),"Duplicate Exp start","OK")))))))))))) | O11: =IF(B11="","",B11&IF(T11<>"","_"&T11,"")&IF(C11<>"","_"&C11,"")) | R11: =IF(B11="","",IFERROR(LOOKUP(2,1/($A$3:A11<>""),$A$3:A11),"")) | S11: =IF(B11="","",IF(IFERROR(TEXT(DATE(2000+VALUE(RIGHT(B11,2)),VALUE(MID(B11,4,2)),VALUE(LEFT(B11,2))),"dd.mm.yy")=B11,FALSE),DATE(2000+VALUE(RIGHT(B11,2)),VALUE(MID(B11,4,2)),VALUE(LEFT(B11,2))),"")) | T11: =IF(B11="","",IFERROR(LOOKUP(2,1/(($R$3:R11=R11)*($D$3:D11<>"")),$D$3:D11),"")) | U11: =IF(B11="","",IFERROR(LOOKUP(2,1/(($R$3:R11=R11)*($E$3:E11<>"")),$E$3:E11),"")) | V11: =IF(B11="","",IFERROR(LOOKUP(2,1/(($R$3:R11=R11)*($F$3:F11<>"")),$F$3:F11),"")) | W11: =IF(B11="","",IF(IFERROR(LOOKUP(2,1/(($R$3:R11=R11)*($H$3:H11<>"")),$H$3:H11),"growth")="[none]","",IFERROR(LOOKUP(2,1/(($R$3:R11=R11)*($H$3:H11<>"")),$H$3:H11),"growth"))) | X11: =IF(B11="","",IFERROR(LOOKUP(2,1/(($R$3:R11=R11)*($I$3:I11<>"")),$I$3:I11),".jpg")) | Y11: =IF(OR(B11="",R11="",S11=""),"","E"&R11&"_"&B11&IF(T11<>"","_"&T11,"")&IF(C11<>"","_"&C11,"")) | Z11: =IF(B11="","",IF(IFERROR(LOOKUP(2,1/(($R$3:R11=R11)*($G$3:G11<>"")),$G$3:G11),"")="[none]","",IFERROR(LOOKUP(2,1/(($R$3:R11=R11)*($G$3:G11<>"")),$G$3:G11),"")))
K12: =IF(B12="","",COUNTIF(Arrangements!$M$3:$M$92,U12)) | L12: =IF(OR(B12="",N12<>"OK"),"",1+SUMIFS($K$3:K11,$N$3:N11,"OK")) | M12: =IF(L12="","",L12+K12-1) | N12: =IF(B12="","",IF(J12=FALSE,"Excluded",IF(R12="","Missing Exp",IF(NOT(IFERROR(TEXT(DATE(2000+VALUE(RIGHT(B12,2)),VALUE(MID(B12,4,2)),VALUE(LEFT(B12,2))),"dd.mm.yy")=B12,FALSE)),"Invalid date - use dd.mm.yy",IF(U12="","Missing Arrangement",IF(COUNTIF(Arrangements!$M$3:$M$92,U12)=0,"Unknown Arrangement",IF(SUMPRODUCT((Arrangements!$M$3:$M$92=U12)*(Arrangements!$P$3:$P$92<>"OK"))>0,"Arrangement errors",IF(AND(V12<>"",COUNTIF(Annotations!$B$3:$B$46,V12)=0),"Unknown annotationSet",IF(AND(V12<>"",COUNTIFS(Annotations!$B$3:$B$46,V12,Annotations!$F$3:$F$46,"<>OK")>0),"annotationSet errors",IF(K12=0,"No images",IF(COUNTIF($Y$3:$Y$62,Y12)>1,"Duplicate session - change Name or Time",IF(AND(A12<>"",COUNTIF($A$3:$A$62,A12)>1),"Duplicate Exp start","OK")))))))))))) | O12: =IF(B12="","",B12&IF(T12<>"","_"&T12,"")&IF(C12<>"","_"&C12,"")) | R12: =IF(B12="","",IFERROR(LOOKUP(2,1/($A$3:A12<>""),$A$3:A12),"")) | S12: =IF(B12="","",IF(IFERROR(TEXT(DATE(2000+VALUE(RIGHT(B12,2)),VALUE(MID(B12,4,2)),VALUE(LEFT(B12,2))),"dd.mm.yy")=B12,FALSE),DATE(2000+VALUE(RIGHT(B12,2)),VALUE(MID(B12,4,2)),VALUE(LEFT(B12,2))),"")) | T12: =IF(B12="","",IFERROR(LOOKUP(2,1/(($R$3:R12=R12)*($D$3:D12<>"")),$D$3:D12),"")) | U12: =IF(B12="","",IFERROR(LOOKUP(2,1/(($R$3:R12=R12)*($E$3:E12<>"")),$E$3:E12),"")) | V12: =IF(B12="","",IFERROR(LOOKUP(2,1/(($R$3:R12=R12)*($F$3:F12<>"")),$F$3:F12),"")) | W12: =IF(B12="","",IF(IFERROR(LOOKUP(2,1/(($R$3:R12=R12)*($H$3:H12<>"")),$H$3:H12),"growth")="[none]","",IFERROR(LOOKUP(2,1/(($R$3:R12=R12)*($H$3:H12<>"")),$H$3:H12),"growth"))) | X12: =IF(B12="","",IFERROR(LOOKUP(2,1/(($R$3:R12=R12)*($I$3:I12<>"")),$I$3:I12),".jpg")) | Y12: =IF(OR(B12="",R12="",S12=""),"","E"&R12&"_"&B12&IF(T12<>"","_"&T12,"")&IF(C12<>"","_"&C12,"")) | Z12: =IF(B12="","",IF(IFERROR(LOOKUP(2,1/(($R$3:R12=R12)*($G$3:G12<>"")),$G$3:G12),"")="[none]","",IFERROR(LOOKUP(2,1/(($R$3:R12=R12)*($G$3:G12<>"")),$G$3:G12),"")))
K13: =IF(B13="","",COUNTIF(Arrangements!$M$3:$M$92,U13)) | L13: =IF(OR(B13="",N13<>"OK"),"",1+SUMIFS($K$3:K12,$N$3:N12,"OK")) | M13: =IF(L13="","",L13+K13-1) | N13: =IF(B13="","",IF(J13=FALSE,"Excluded",IF(R13="","Missing Exp",IF(NOT(IFERROR(TEXT(DATE(2000+VALUE(RIGHT(B13,2)),VALUE(MID(B13,4,2)),VALUE(LEFT(B13,2))),"dd.mm.yy")=B13,FALSE)),"Invalid date - use dd.mm.yy",IF(U13="","Missing Arrangement",IF(COUNTIF(Arrangements!$M$3:$M$92,U13)=0,"Unknown Arrangement",IF(SUMPRODUCT((Arrangements!$M$3:$M$92=U13)*(Arrangements!$P$3:$P$92<>"OK"))>0,"Arrangement errors",IF(AND(V13<>"",COUNTIF(Annotations!$B$3:$B$46,V13)=0),"Unknown annotationSet",IF(AND(V13<>"",COUNTIFS(Annotations!$B$3:$B$46,V13,Annotations!$F$3:$F$46,"<>OK")>0),"annotationSet errors",IF(K13=0,"No images",IF(COUNTIF($Y$3:$Y$62,Y13)>1,"Duplicate session - change Name or Time",IF(AND(A13<>"",COUNTIF($A$3:$A$62,A13)>1),"Duplicate Exp start","OK")))))))))))) | O13: =IF(B13="","",B13&IF(T13<>"","_"&T13,"")&IF(C13<>"","_"&C13,"")) | R13: =IF(B13="","",IFERROR(LOOKUP(2,1/($A$3:A13<>""),$A$3:A13),"")) | S13: =IF(B13="","",IF(IFERROR(TEXT(DATE(2000+VALUE(RIGHT(B13,2)),VALUE(MID(B13,4,2)),VALUE(LEFT(B13,2))),"dd.mm.yy")=B13,FALSE),DATE(2000+VALUE(RIGHT(B13,2)),VALUE(MID(B13,4,2)),VALUE(LEFT(B13,2))),"")) | T13: =IF(B13="","",IFERROR(LOOKUP(2,1/(($R$3:R13=R13)*($D$3:D13<>"")),$D$3:D13),"")) | U13: =IF(B13="","",IFERROR(LOOKUP(2,1/(($R$3:R13=R13)*($E$3:E13<>"")),$E$3:E13),"")) | V13: =IF(B13="","",IFERROR(LOOKUP(2,1/(($R$3:R13=R13)*($F$3:F13<>"")),$F$3:F13),"")) | W13: =IF(B13="","",IF(IFERROR(LOOKUP(2,1/(($R$3:R13=R13)*($H$3:H13<>"")),$H$3:H13),"growth")="[none]","",IFERROR(LOOKUP(2,1/(($R$3:R13=R13)*($H$3:H13<>"")),$H$3:H13),"growth"))) | X13: =IF(B13="","",IFERROR(LOOKUP(2,1/(($R$3:R13=R13)*($I$3:I13<>"")),$I$3:I13),".jpg")) | Y13: =IF(OR(B13="",R13="",S13=""),"","E"&R13&"_"&B13&IF(T13<>"","_"&T13,"")&IF(C13<>"","_"&C13,"")) | Z13: =IF(B13="","",IF(IFERROR(LOOKUP(2,1/(($R$3:R13=R13)*($G$3:G13<>"")),$G$3:G13),"")="[none]","",IFERROR(LOOKUP(2,1/(($R$3:R13=R13)*($G$3:G13<>"")),$G$3:G13),"")))
K14: =IF(B14="","",COUNTIF(Arrangements!$M$3:$M$92,U14)) | L14: =IF(OR(B14="",N14<>"OK"),"",1+SUMIFS($K$3:K13,$N$3:N13,"OK")) | M14: =IF(L14="","",L14+K14-1) | N14: =IF(B14="","",IF(J14=FALSE,"Excluded",IF(R14="","Missing Exp",IF(NOT(IFERROR(TEXT(DATE(2000+VALUE(RIGHT(B14,2)),VALUE(MID(B14,4,2)),VALUE(LEFT(B14,2))),"dd.mm.yy")=B14,FALSE)),"Invalid date - use dd.mm.yy",IF(U14="","Missing Arrangement",IF(COUNTIF(Arrangements!$M$3:$M$92,U14)=0,"Unknown Arrangement",IF(SUMPRODUCT((Arrangements!$M$3:$M$92=U14)*(Arrangements!$P$3:$P$92<>"OK"))>0,"Arrangement errors",IF(AND(V14<>"",COUNTIF(Annotations!$B$3:$B$46,V14)=0),"Unknown annotationSet",IF(AND(V14<>"",COUNTIFS(Annotations!$B$3:$B$46,V14,Annotations!$F$3:$F$46,"<>OK")>0),"annotationSet errors",IF(K14=0,"No images",IF(COUNTIF($Y$3:$Y$62,Y14)>1,"Duplicate session - change Name or Time",IF(AND(A14<>"",COUNTIF($A$3:$A$62,A14)>1),"Duplicate Exp start","OK")))))))))))) | O14: =IF(B14="","",B14&IF(T14<>"","_"&T14,"")&IF(C14<>"","_"&C14,"")) | R14: =IF(B14="","",IFERROR(LOOKUP(2,1/($A$3:A14<>""),$A$3:A14),"")) | S14: =IF(B14="","",IF(IFERROR(TEXT(DATE(2000+VALUE(RIGHT(B14,2)),VALUE(MID(B14,4,2)),VALUE(LEFT(B14,2))),"dd.mm.yy")=B14,FALSE),DATE(2000+VALUE(RIGHT(B14,2)),VALUE(MID(B14,4,2)),VALUE(LEFT(B14,2))),"")) | T14: =IF(B14="","",IFERROR(LOOKUP(2,1/(($R$3:R14=R14)*($D$3:D14<>"")),$D$3:D14),"")) | U14: =IF(B14="","",IFERROR(LOOKUP(2,1/(($R$3:R14=R14)*($E$3:E14<>"")),$E$3:E14),"")) | V14: =IF(B14="","",IFERROR(LOOKUP(2,1/(($R$3:R14=R14)*($F$3:F14<>"")),$F$3:F14),"")) | W14: =IF(B14="","",IF(IFERROR(LOOKUP(2,1/(($R$3:R14=R14)*($H$3:H14<>"")),$H$3:H14),"growth")="[none]","",IFERROR(LOOKUP(2,1/(($R$3:R14=R14)*($H$3:H14<>"")),$H$3:H14),"growth"))) | X14: =IF(B14="","",IFERROR(LOOKUP(2,1/(($R$3:R14=R14)*($I$3:I14<>"")),$I$3:I14),".jpg")) | Y14: =IF(OR(B14="",R14="",S14=""),"","E"&R14&"_"&B14&IF(T14<>"","_"&T14,"")&IF(C14<>"","_"&C14,"")) | Z14: =IF(B14="","",IF(IFERROR(LOOKUP(2,1/(($R$3:R14=R14)*($G$3:G14<>"")),$G$3:G14),"")="[none]","",IFERROR(LOOKUP(2,1/(($R$3:R14=R14)*($G$3:G14<>"")),$G$3:G14),"")))
K15: =IF(B15="","",COUNTIF(Arrangements!$M$3:$M$92,U15)) | L15: =IF(OR(B15="",N15<>"OK"),"",1+SUMIFS($K$3:K14,$N$3:N14,"OK")) | M15: =IF(L15="","",L15+K15-1) | N15: =IF(B15="","",IF(J15=FALSE,"Excluded",IF(R15="","Missing Exp",IF(NOT(IFERROR(TEXT(DATE(2000+VALUE(RIGHT(B15,2)),VALUE(MID(B15,4,2)),VALUE(LEFT(B15,2))),"dd.mm.yy")=B15,FALSE)),"Invalid date - use dd.mm.yy",IF(U15="","Missing Arrangement",IF(COUNTIF(Arrangements!$M$3:$M$92,U15)=0,"Unknown Arrangement",IF(SUMPRODUCT((Arrangements!$M$3:$M$92=U15)*(Arrangements!$P$3:$P$92<>"OK"))>0,"Arrangement errors",IF(AND(V15<>"",COUNTIF(Annotations!$B$3:$B$46,V15)=0),"Unknown annotationSet",IF(AND(V15<>"",COUNTIFS(Annotations!$B$3:$B$46,V15,Annotations!$F$3:$F$46,"<>OK")>0),"annotationSet errors",IF(K15=0,"No images",IF(COUNTIF($Y$3:$Y$62,Y15)>1,"Duplicate session - change Name or Time",IF(AND(A15<>"",COUNTIF($A$3:$A$62,A15)>1),"Duplicate Exp start","OK")))))))))))) | O15: =IF(B15="","",B15&IF(T15<>"","_"&T15,"")&IF(C15<>"","_"&C15,"")) | R15: =IF(B15="","",IFERROR(LOOKUP(2,1/($A$3:A15<>""),$A$3:A15),"")) | S15: =IF(B15="","",IF(IFERROR(TEXT(DATE(2000+VALUE(RIGHT(B15,2)),VALUE(MID(B15,4,2)),VALUE(LEFT(B15,2))),"dd.mm.yy")=B15,FALSE),DATE(2000+VALUE(RIGHT(B15,2)),VALUE(MID(B15,4,2)),VALUE(LEFT(B15,2))),"")) | T15: =IF(B15="","",IFERROR(LOOKUP(2,1/(($R$3:R15=R15)*($D$3:D15<>"")),$D$3:D15),"")) | U15: =IF(B15="","",IFERROR(LOOKUP(2,1/(($R$3:R15=R15)*($E$3:E15<>"")),$E$3:E15),"")) | V15: =IF(B15="","",IFERROR(LOOKUP(2,1/(($R$3:R15=R15)*($F$3:F15<>"")),$F$3:F15),"")) | W15: =IF(B15="","",IF(IFERROR(LOOKUP(2,1/(($R$3:R15=R15)*($H$3:H15<>"")),$H$3:H15),"growth")="[none]","",IFERROR(LOOKUP(2,1/(($R$3:R15=R15)*($H$3:H15<>"")),$H$3:H15),"growth"))) | X15: =IF(B15="","",IFERROR(LOOKUP(2,1/(($R$3:R15=R15)*($I$3:I15<>"")),$I$3:I15),".jpg")) | Y15: =IF(OR(B15="",R15="",S15=""),"","E"&R15&"_"&B15&IF(T15<>"","_"&T15,"")&IF(C15<>"","_"&C15,"")) | Z15: =IF(B15="","",IF(IFERROR(LOOKUP(2,1/(($R$3:R15=R15)*($G$3:G15<>"")),$G$3:G15),"")="[none]","",IFERROR(LOOKUP(2,1/(($R$3:R15=R15)*($G$3:G15<>"")),$G$3:G15),"")))
K16: =IF(B16="","",COUNTIF(Arrangements!$M$3:$M$92,U16)) | L16: =IF(OR(B16="",N16<>"OK"),"",1+SUMIFS($K$3:K15,$N$3:N15,"OK")) | M16: =IF(L16="","",L16+K16-1) | N16: =IF(B16="","",IF(J16=FALSE,"Excluded",IF(R16="","Missing Exp",IF(NOT(IFERROR(TEXT(DATE(2000+VALUE(RIGHT(B16,2)),VALUE(MID(B16,4,2)),VALUE(LEFT(B16,2))),"dd.mm.yy")=B16,FALSE)),"Invalid date - use dd.mm.yy",IF(U16="","Missing Arrangement",IF(COUNTIF(Arrangements!$M$3:$M$92,U16)=0,"Unknown Arrangement",IF(SUMPRODUCT((Arrangements!$M$3:$M$92=U16)*(Arrangements!$P$3:$P$92<>"OK"))>0,"Arrangement errors",IF(AND(V16<>"",COUNTIF(Annotations!$B$3:$B$46,V16)=0),"Unknown annotationSet",IF(AND(V16<>"",COUNTIFS(Annotations!$B$3:$B$46,V16,Annotations!$F$3:$F$46,"<>OK")>0),"annotationSet errors",IF(K16=0,"No images",IF(COUNTIF($Y$3:$Y$62,Y16)>1,"Duplicate session - change Name or Time",IF(AND(A16<>"",COUNTIF($A$3:$A$62,A16)>1),"Duplicate Exp start","OK")))))))))))) | O16: =IF(B16="","",B16&IF(T16<>"","_"&T16,"")&IF(C16<>"","_"&C16,"")) | R16: =IF(B16="","",IFERROR(LOOKUP(2,1/($A$3:A16<>""),$A$3:A16),"")) | S16: =IF(B16="","",IF(IFERROR(TEXT(DATE(2000+VALUE(RIGHT(B16,2)),VALUE(MID(B16,4,2)),VALUE(LEFT(B16,2))),"dd.mm.yy")=B16,FALSE),DATE(2000+VALUE(RIGHT(B16,2)),VALUE(MID(B16,4,2)),VALUE(LEFT(B16,2))),"")) | T16: =IF(B16="","",IFERROR(LOOKUP(2,1/(($R$3:R16=R16)*($D$3:D16<>"")),$D$3:D16),"")) | U16: =IF(B16="","",IFERROR(LOOKUP(2,1/(($R$3:R16=R16)*($E$3:E16<>"")),$E$3:E16),"")) | V16: =IF(B16="","",IFERROR(LOOKUP(2,1/(($R$3:R16=R16)*($F$3:F16<>"")),$F$3:F16),"")) | W16: =IF(B16="","",IF(IFERROR(LOOKUP(2,1/(($R$3:R16=R16)*($H$3:H16<>"")),$H$3:H16),"growth")="[none]","",IFERROR(LOOKUP(2,1/(($R$3:R16=R16)*($H$3:H16<>"")),$H$3:H16),"growth"))) | X16: =IF(B16="","",IFERROR(LOOKUP(2,1/(($R$3:R16=R16)*($I$3:I16<>"")),$I$3:I16),".jpg")) | Y16: =IF(OR(B16="",R16="",S16=""),"","E"&R16&"_"&B16&IF(T16<>"","_"&T16,"")&IF(C16<>"","_"&C16,"")) | Z16: =IF(B16="","",IF(IFERROR(LOOKUP(2,1/(($R$3:R16=R16)*($G$3:G16<>"")),$G$3:G16),"")="[none]","",IFERROR(LOOKUP(2,1/(($R$3:R16=R16)*($G$3:G16<>"")),$G$3:G16),"")))
K17: =IF(B17="","",COUNTIF(Arrangements!$M$3:$M$92,U17)) | L17: =IF(OR(B17="",N17<>"OK"),"",1+SUMIFS($K$3:K16,$N$3:N16,"OK")) | M17: =IF(L17="","",L17+K17-1) | N17: =IF(B17="","",IF(J17=FALSE,"Excluded",IF(R17="","Missing Exp",IF(NOT(IFERROR(TEXT(DATE(2000+VALUE(RIGHT(B17,2)),VALUE(MID(B17,4,2)),VALUE(LEFT(B17,2))),"dd.mm.yy")=B17,FALSE)),"Invalid date - use dd.mm.yy",IF(U17="","Missing Arrangement",IF(COUNTIF(Arrangements!$M$3:$M$92,U17)=0,"Unknown Arrangement",IF(SUMPRODUCT((Arrangements!$M$3:$M$92=U17)*(Arrangements!$P$3:$P$92<>"OK"))>0,"Arrangement errors",IF(AND(V17<>"",COUNTIF(Annotations!$B$3:$B$46,V17)=0),"Unknown annotationSet",IF(AND(V17<>"",COUNTIFS(Annotations!$B$3:$B$46,V17,Annotations!$F$3:$F$46,"<>OK")>0),"annotationSet errors",IF(K17=0,"No images",IF(COUNTIF($Y$3:$Y$62,Y17)>1,"Duplicate session - change Name or Time",IF(AND(A17<>"",COUNTIF($A$3:$A$62,A17)>1),"Duplicate Exp start","OK")))))))))))) | O17: =IF(B17="","",B17&IF(T17<>"","_"&T17,"")&IF(C17<>"","_"&C17,"")) | R17: =IF(B17="","",IFERROR(LOOKUP(2,1/($A$3:A17<>""),$A$3:A17),"")) | S17: =IF(B17="","",IF(IFERROR(TEXT(DATE(2000+VALUE(RIGHT(B17,2)),VALUE(MID(B17,4,2)),VALUE(LEFT(B17,2))),"dd.mm.yy")=B17,FALSE),DATE(2000+VALUE(RIGHT(B17,2)),VALUE(MID(B17,4,2)),VALUE(LEFT(B17,2))),"")) | T17: =IF(B17="","",IFERROR(LOOKUP(2,1/(($R$3:R17=R17)*($D$3:D17<>"")),$D$3:D17),"")) | U17: =IF(B17="","",IFERROR(LOOKUP(2,1/(($R$3:R17=R17)*($E$3:E17<>"")),$E$3:E17),"")) | V17: =IF(B17="","",IFERROR(LOOKUP(2,1/(($R$3:R17=R17)*($F$3:F17<>"")),$F$3:F17),"")) | W17: =IF(B17="","",IF(IFERROR(LOOKUP(2,1/(($R$3:R17=R17)*($H$3:H17<>"")),$H$3:H17),"growth")="[none]","",IFERROR(LOOKUP(2,1/(($R$3:R17=R17)*($H$3:H17<>"")),$H$3:H17),"growth"))) | X17: =IF(B17="","",IFERROR(LOOKUP(2,1/(($R$3:R17=R17)*($I$3:I17<>"")),$I$3:I17),".jpg")) | Y17: =IF(OR(B17="",R17="",S17=""),"","E"&R17&"_"&B17&IF(T17<>"","_"&T17,"")&IF(C17<>"","_"&C17,"")) | Z17: =IF(B17="","",IF(IFERROR(LOOKUP(2,1/(($R$3:R17=R17)*($G$3:G17<>"")),$G$3:G17),"")="[none]","",IFERROR(LOOKUP(2,1/(($R$3:R17=R17)*($G$3:G17<>"")),$G$3:G17),"")))
K18: =IF(B18="","",COUNTIF(Arrangements!$M$3:$M$92,U18)) | L18: =IF(OR(B18="",N18<>"OK"),"",1+SUMIFS($K$3:K17,$N$3:N17,"OK")) | M18: =IF(L18="","",L18+K18-1) | N18: =IF(B18="","",IF(J18=FALSE,"Excluded",IF(R18="","Missing Exp",IF(NOT(IFERROR(TEXT(DATE(2000+VALUE(RIGHT(B18,2)),VALUE(MID(B18,4,2)),VALUE(LEFT(B18,2))),"dd.mm.yy")=B18,FALSE)),"Invalid date - use dd.mm.yy",IF(U18="","Missing Arrangement",IF(COUNTIF(Arrangements!$M$3:$M$92,U18)=0,"Unknown Arrangement",IF(SUMPRODUCT((Arrangements!$M$3:$M$92=U18)*(Arrangements!$P$3:$P$92<>"OK"))>0,"Arrangement errors",IF(AND(V18<>"",COUNTIF(Annotations!$B$3:$B$46,V18)=0),"Unknown annotationSet",IF(AND(V18<>"",COUNTIFS(Annotations!$B$3:$B$46,V18,Annotations!$F$3:$F$46,"<>OK")>0),"annotationSet errors",IF(K18=0,"No images",IF(COUNTIF($Y$3:$Y$62,Y18)>1,"Duplicate session - change Name or Time",IF(AND(A18<>"",COUNTIF($A$3:$A$62,A18)>1),"Duplicate Exp start","OK")))))))))))) | O18: =IF(B18="","",B18&IF(T18<>"","_"&T18,"")&IF(C18<>"","_"&C18,"")) | R18: =IF(B18="","",IFERROR(LOOKUP(2,1/($A$3:A18<>""),$A$3:A18),"")) | S18: =IF(B18="","",IF(IFERROR(TEXT(DATE(2000+VALUE(RIGHT(B18,2)),VALUE(MID(B18,4,2)),VALUE(LEFT(B18,2))),"dd.mm.yy")=B18,FALSE),DATE(2000+VALUE(RIGHT(B18,2)),VALUE(MID(B18,4,2)),VALUE(LEFT(B18,2))),"")) | T18: =IF(B18="","",IFERROR(LOOKUP(2,1/(($R$3:R18=R18)*($D$3:D18<>"")),$D$3:D18),"")) | U18: =IF(B18="","",IFERROR(LOOKUP(2,1/(($R$3:R18=R18)*($E$3:E18<>"")),$E$3:E18),"")) | V18: =IF(B18="","",IFERROR(LOOKUP(2,1/(($R$3:R18=R18)*($F$3:F18<>"")),$F$3:F18),"")) | W18: =IF(B18="","",IF(IFERROR(LOOKUP(2,1/(($R$3:R18=R18)*($H$3:H18<>"")),$H$3:H18),"growth")="[none]","",IFERROR(LOOKUP(2,1/(($R$3:R18=R18)*($H$3:H18<>"")),$H$3:H18),"growth"))) | X18: =IF(B18="","",IFERROR(LOOKUP(2,1/(($R$3:R18=R18)*($I$3:I18<>"")),$I$3:I18),".jpg")) | Y18: =IF(OR(B18="",R18="",S18=""),"","E"&R18&"_"&B18&IF(T18<>"","_"&T18,"")&IF(C18<>"","_"&C18,"")) | Z18: =IF(B18="","",IF(IFERROR(LOOKUP(2,1/(($R$3:R18=R18)*($G$3:G18<>"")),$G$3:G18),"")="[none]","",IFERROR(LOOKUP(2,1/(($R$3:R18=R18)*($G$3:G18<>"")),$G$3:G18),"")))
... K32: =IF(B32="","",COUNTIF(Arrangements!$M$3:$M$92,U32)) | L32: =IF(OR(B32="",N32<>"OK"),"",1+SUMIFS($K$3:K31,$N$3:N31,"OK")) | M32: =IF(L32="","",L32+K32-1) | N32: =IF(B32="","",IF(J32=FALSE,"Excluded",IF(R32="","Missing Exp",IF(NOT(IFERROR(TEXT(DATE(2000+VALUE(RIGHT(B32,2)),VALUE(MID(B32,4,2)),VALUE(LEFT(B32,2))),"dd.mm.yy")=B32,FALSE)),"Invalid date - use dd.mm.yy",IF(U32="","Missing Arrangement",IF(COUNTIF(Arrangements!$M$3:$M$92,U32)=0,"Unknown Arrangement",IF(SUMPRODUCT((Arrangements!$M$3:$M$92=U32)*(Arrangements!$P$3:$P$92<>"OK"))>0,"Arrangement errors",IF(AND(V32<>"",COUNTIF(Annotations!$B$3:$B$46,V32)=0),"Unknown annotationSet",IF(AND(V32<>"",COUNTIFS(Annotations!$B$3:$B$46,V32,Annotations!$F$3:$F$46,"<>OK")>0),"annotationSet errors",IF(K32=0,"No images",IF(COUNTIF($Y$3:$Y$62,Y32)>1,"Duplicate session - change Name or Time",IF(AND(A32<>"",COUNTIF($A$3:$A$62,A32)>1),"Duplicate Exp start","OK")))))))))))) | O32: =IF(B32="","",B32&IF(T32<>"","_"&T32,"")&IF(C32<>"","_"&C32,"")) | R32: =IF(B32="","",IFERROR(LOOKUP(2,1/($A$3:A32<>""),$A$3:A32),"")) | S32: =IF(B32="","",IF(IFERROR(TEXT(DATE(2000+VALUE(RIGHT(B32,2)),VALUE(MID(B32,4,2)),VALUE(LEFT(B32,2))),"dd.mm.yy")=B32,FALSE),DATE(2000+VALUE(RIGHT(B32,2)),VALUE(MID(B32,4,2)),VALUE(LEFT(B32,2))),"")) | T32: =IF(B32="","",IFERROR(LOOKUP(2,1/(($R$3:R32=R32)*($D$3:D32<>"")),$D$3:D32),"")) | U32: =IF(B32="","",IFERROR(LOOKUP(2,1/(($R$3:R32=R32)*($E$3:E32<>"")),$E$3:E32),"")) | V32: =IF(B32="","",IFERROR(LOOKUP(2,1/(($R$3:R32=R32)*($F$3:F32<>"")),$F$3:F32),"")) | W32: =IF(B32="","",IF(IFERROR(LOOKUP(2,1/(($R$3:R32=R32)*($H$3:H32<>"")),$H$3:H32),"growth")="[none]","",IFERROR(LOOKUP(2,1/(($R$3:R32=R32)*($H$3:H32<>"")),$H$3:H32),"growth"))) | X32: =IF(B32="","",IFERROR(LOOKUP(2,1/(($R$3:R32=R32)*($I$3:I32<>"")),$I$3:I32),".jpg")) | Y32: =IF(OR(B32="",R32="",S32=""),"","E"&R32&"_"&B32&IF(T32<>"","_"&T32,"")&IF(C32<>"","_"&C32,"")) | Z32: =IF(B32="","",IF(IFERROR(LOOKUP(2,1/(($R$3:R32=R32)*($G$3:G32<>"")),$G$3:G32),"")="[none]","",IFERROR(LOOKUP(2,1/(($R$3:R32=R32)*($G$3:G32<>"")),$G$3:G32),"")))
Z33: =IF(B33="","",IF(IFERROR(LOOKUP(2,1/(($R$3:R33=R33)*($G$3:G33<>"")),$G$3:G33),"")="[none]","",IFERROR(LOOKUP(2,1/(($R$3:R33=R33)*($G$3:G33<>"")),$G$3:G33),"")))
Z34: =IF(B34="","",IF(IFERROR(LOOKUP(2,1/(($R$3:R34=R34)*($G$3:G34<>"")),$G$3:G34),"")="[none]","",IFERROR(LOOKUP(2,1/(($R$3:R34=R34)*($G$3:G34<>"")),$G$3:G34),"")))
Z35: =IF(B35="","",IF(IFERROR(LOOKUP(2,1/(($R$3:R35=R35)*($G$3:G35<>"")),$G$3:G35),"")="[none]","",IFERROR(LOOKUP(2,1/(($R$3:R35=R35)*($G$3:G35<>"")),$G$3:G35),"")))
Z36: =IF(B36="","",IF(IFERROR(LOOKUP(2,1/(($R$3:R36=R36)*($G$3:G36<>"")),$G$3:G36),"")="[none]","",IFERROR(LOOKUP(2,1/(($R$3:R36=R36)*($G$3:G36<>"")),$G$3:G36),"")))
Z37: =IF(B37="","",IF(IFERROR(LOOKUP(2,1/(($R$3:R37=R37)*($G$3:G37<>"")),$G$3:G37),"")="[none]","",IFERROR(LOOKUP(2,1/(($R$3:R37=R37)*($G$3:G37<>"")),$G$3:G37),"")))
Z38: =IF(B38="","",IF(IFERROR(LOOKUP(2,1/(($R$3:R38=R38)*($G$3:G38<>"")),$G$3:G38),"")="[none]","",IFERROR(LOOKUP(2,1/(($R$3:R38=R38)*($G$3:G38<>"")),$G$3:G38),"")))
Z39: =IF(B39="","",IF(IFERROR(LOOKUP(2,1/(($R$3:R39=R39)*($G$3:G39<>"")),$G$3:G39),"")="[none]","",IFERROR(LOOKUP(2,1/(($R$3:R39=R39)*($G$3:G39<>"")),$G$3:G39),"")))
Z40: =IF(B40="","",IF(IFERROR(LOOKUP(2,1/(($R$3:R40=R40)*($G$3:G40<>"")),$G$3:G40),"")="[none]","",IFERROR(LOOKUP(2,1/(($R$3:R40=R40)*($G$3:G40<>"")),$G$3:G40),"")))
Z41: =IF(B41="","",IF(IFERROR(LOOKUP(2,1/(($R$3:R41=R41)*($G$3:G41<>"")),$G$3:G41),"")="[none]","",IFERROR(LOOKUP(2,1/(($R$3:R41=R41)*($G$3:G41<>"")),$G$3:G41),"")))
Z42: =IF(B42="","",IF(IFERROR(LOOKUP(2,1/(($R$3:R42=R42)*($G$3:G42<>"")),$G$3:G42),"")="[none]","",IFERROR(LOOKUP(2,1/(($R$3:R42=R42)*($G$3:G42<>"")),$G$3:G42),"")))
Z43: =IF(B43="","",IF(IFERROR(LOOKUP(2,1/(($R$3:R43=R43)*($G$3:G43<>"")),$G$3:G43),"")="[none]","",IFERROR(LOOKUP(2,1/(($R$3:R43=R43)*($G$3:G43<>"")),$G$3:G43),"")))
Z44: =IF(B44="","",IF(IFERROR(LOOKUP(2,1/(($R$3:R44=R44)*($G$3:G44<>"")),$G$3:G44),"")="[none]","",IFERROR(LOOKUP(2,1/(($R$3:R44=R44)*($G$3:G44<>"")),$G$3:G44),"")))
... Z62: =IF(B62="","",IF(IFERROR(LOOKUP(2,1/(($R$3:R62=R62)*($G$3:G62<>"")),$G$3:G62),"")="[none]","",IFERROR(LOOKUP(2,1/(($R$3:R62=R62)*($G$3:G62<>"")),$G$3:G62),"")))

Sheet Arrangements
A1: ARRANGEMENTS — REUSABLE IMAGE / SAMPLE ORDER | J1: CONTROLS | M1: RESOLVED MACHINE FIELDS | AY1: Active highlight | AZ1: TRUE
A2: Date | B2: Arrangement | C2: Image # | D2: Sample description | E2: Set | F2: Media | G2: Condition | H2: Rep # | J2: VBA controls | M2: Arrangement* | N2: Condition* | O2: Group key* | P2: Check* | AY2: Legend visible | AZ2: FALSE
A3: =IF(M3="","",IFERROR(INDEX(Overview!$B$3:$B$62,MATCH(M3,Overview!$U$3:$U$62,0)),"")) -> 14.08.26 | B3: Arrangement 1 | C3: =IF(M3="","",COUNTIF($M$3:M3,M3)) -> 1 | D3: =IF(M3="","",IF(AND(F3="",G3=""),"",IF(F3<>"",F3,"")&IF(AND(F3<>"",G3<>"")," + ","")&IF(G3<>"",G3,"")&IF(H3<>"",", "&H3,""))) -> YPDA, 1 | E3: A | F3: YPDA | H3: =IF(OR(M3="",E3=""),"",IF(COUNTIF($O$3:$O$92,O3)>1,COUNTIF($O$3:O3,O3),"")) -> 1 | J3: LIVE / PAUSED | M3: =IF(COUNTA(E3:G3)=0,"",IF(B3<>"",B3,"")) -> Arrangement 1 | N3: =IF(M3="","",IF(G3="","[control]",G3)) -> [control] | O3: =IF(M3="","",M3&"|"&E3&"|"&IF(F3="","[blank]",F3)&"|"&N3) -> Arrangement 1|A|YPDA|[control] | P3: =IF(M3="","",IF(E3="","Missing Set",IF(AND(B3<>"",COUNTIF($B$3:$B$92,B3)>1),"Duplicate Arrangement start",IF(D3="","Blank description","OK")))) -> OK | AY3: VBA live | AZ3: FALSE
A4: =IF(M4="","",IFERROR(INDEX(Overview!$B$3:$B$62,MATCH(M4,Overview!$U$3:$U$62,0)),"")) -> 14.08.26 | C4: =IF(M4="","",COUNTIF($M$3:M4,M4)) -> 2 | D4: =IF(M4="","",IF(AND(F4="",G4=""),"",IF(F4<>"",F4,"")&IF(AND(F4<>"",G4<>"")," + ","")&IF(G4<>"",G4,"")&IF(H4<>"",", "&H4,""))) -> YPDA, 2 | E4: A | F4: YPDA | H4: =IF(OR(M4="",E4=""),"",IF(COUNTIF($O$3:$O$92,O4)>1,COUNTIF($O$3:O4,O4),"")) -> 2 | J4: Sync Now | M4: =IF(COUNTA(E4:G4)=0,"",IF(B4<>"",B4,M3)) -> Arrangement 1 | N4: =IF(M4="","",IF(G4="","[control]",G4)) -> [control] | O4: =IF(M4="","",M4&"|"&E4&"|"&IF(F4="","[blank]",F4)&"|"&N4) -> Arrangement 1|A|YPDA|[control] | P4: =IF(M4="","",IF(E4="","Missing Set",IF(AND(B4<>"",COUNTIF($B$3:$B$92,B4)>1),"Duplicate Arrangement start",IF(D4="","Blank description","OK")))) -> OK | AY4: Sync pending | AZ4: FALSE
A5: =IF(M5="","",IFERROR(INDEX(Overview!$B$3:$B$62,MATCH(M5,Overview!$U$3:$U$62,0)),"")) -> 14.08.26 | C5: =IF(M5="","",COUNTIF($M$3:M5,M5)) -> 3 | D5: =IF(M5="","",IF(AND(F5="",G5=""),"",IF(F5<>"",F5,"")&IF(AND(F5<>"",G5<>"")," + ","")&IF(G5<>"",G5,"")&IF(H5<>"",", "&H5,""))) -> YPDA, 3 | E5: A | F5: YPDA | H5: =IF(OR(M5="",E5=""),"",IF(COUNTIF($O$3:$O$92,O5)>1,COUNTIF($O$3:O5,O5),"")) -> 3 | J5: Legend (bottom) | M5: =IF(COUNTA(E5:G5)=0,"",IF(B5<>"",B5,M4)) -> Arrangement 1 | N5: =IF(M5="","",IF(G5="","[control]",G5)) -> [control] | O5: =IF(M5="","",M5&"|"&E5&"|"&IF(F5="","[blank]",F5)&"|"&N5) -> Arrangement 1|A|YPDA|[control] | P5: =IF(M5="","",IF(E5="","Missing Set",IF(AND(B5<>"",COUNTIF($B$3:$B$92,B5)>1),"Duplicate Arrangement start",IF(D5="","Blank description","OK")))) -> OK | AY5: Capacity row | AZ5: 92
A6: =IF(M6="","",IFERROR(INDEX(Overview!$B$3:$B$62,MATCH(M6,Overview!$U$3:$U$62,0)),"")) -> 14.08.26 | C6: =IF(M6="","",COUNTIF($M$3:M6,M6)) -> 4 | D6: =IF(M6="","",IF(AND(F6="",G6=""),"",IF(F6<>"",F6,"")&IF(AND(F6<>"",G6<>"")," + ","")&IF(G6<>"",G6,"")&IF(H6<>"",", "&H6,""))) -> YPDA, 4 | E6: A | F6: YPDA | H6: =IF(OR(M6="",E6=""),"",IF(COUNTIF($O$3:$O$92,O6)>1,COUNTIF($O$3:O6,O6),"")) -> 4 | M6: =IF(COUNTA(E6:G6)=0,"",IF(B6<>"",B6,M5)) -> Arrangement 1 | N6: =IF(M6="","",IF(G6="","[control]",G6)) -> [control] | O6: =IF(M6="","",M6&"|"&E6&"|"&IF(F6="","[blank]",F6)&"|"&N6) -> Arrangement 1|A|YPDA|[control] | P6: =IF(M6="","",IF(E6="","Missing Set",IF(AND(B6<>"",COUNTIF($B$3:$B$92,B6)>1),"Duplicate Arrangement start",IF(D6="","Blank description","OK")))) -> OK
A7: =IF(M7="","",IFERROR(INDEX(Overview!$B$3:$B$62,MATCH(M7,Overview!$U$3:$U$62,0)),"")) -> 14.08.26 | C7: =IF(M7="","",COUNTIF($M$3:M7,M7)) -> 5 | D7: =IF(M7="","",IF(AND(F7="",G7=""),"",IF(F7<>"",F7,"")&IF(AND(F7<>"",G7<>"")," + ","")&IF(G7<>"",G7,"")&IF(H7<>"",", "&H7,""))) -> YPDA + heat, 1 | E7: A | F7: YPDA | G7: heat | H7: =IF(OR(M7="",E7=""),"",IF(COUNTIF($O$3:$O$92,O7)>1,COUNTIF($O$3:O7,O7),"")) -> 1 | M7: =IF(COUNTA(E7:G7)=0,"",IF(B7<>"",B7,M6)) -> Arrangement 1 | N7: =IF(M7="","",IF(G7="","[control]",G7)) -> heat | O7: =IF(M7="","",M7&"|"&E7&"|"&IF(F7="","[blank]",F7)&"|"&N7) -> Arrangement 1|A|YPDA|heat | P7: =IF(M7="","",IF(E7="","Missing Set",IF(AND(B7<>"",COUNTIF($B$3:$B$92,B7)>1),"Duplicate Arrangement start",IF(D7="","Blank description","OK")))) -> OK
A8: =IF(M8="","",IFERROR(INDEX(Overview!$B$3:$B$62,MATCH(M8,Overview!$U$3:$U$62,0)),"")) -> 14.08.26 | C8: =IF(M8="","",COUNTIF($M$3:M8,M8)) -> 6 | D8: =IF(M8="","",IF(AND(F8="",G8=""),"",IF(F8<>"",F8,"")&IF(AND(F8<>"",G8<>"")," + ","")&IF(G8<>"",G8,"")&IF(H8<>"",", "&H8,""))) -> YPDA + heat, 2 | E8: A | F8: YPDA | G8: heat | H8: =IF(OR(M8="",E8=""),"",IF(COUNTIF($O$3:$O$92,O8)>1,COUNTIF($O$3:O8,O8),"")) -> 2 | M8: =IF(COUNTA(E8:G8)=0,"",IF(B8<>"",B8,M7)) -> Arrangement 1 | N8: =IF(M8="","",IF(G8="","[control]",G8)) -> heat | O8: =IF(M8="","",M8&"|"&E8&"|"&IF(F8="","[blank]",F8)&"|"&N8) -> Arrangement 1|A|YPDA|heat | P8: =IF(M8="","",IF(E8="","Missing Set",IF(AND(B8<>"",COUNTIF($B$3:$B$92,B8)>1),"Duplicate Arrangement start",IF(D8="","Blank description","OK")))) -> OK
A9: =IF(M9="","",IFERROR(INDEX(Overview!$B$3:$B$62,MATCH(M9,Overview!$U$3:$U$62,0)),"")) -> 14.08.26 | C9: =IF(M9="","",COUNTIF($M$3:M9,M9)) -> 7 | D9: =IF(M9="","",IF(AND(F9="",G9=""),"",IF(F9<>"",F9,"")&IF(AND(F9<>"",G9<>"")," + ","")&IF(G9<>"",G9,"")&IF(H9<>"",", "&H9,""))) -> YPDA + heat, 3 | E9: A | F9: YPDA | G9: heat | H9: =IF(OR(M9="",E9=""),"",IF(COUNTIF($O$3:$O$92,O9)>1,COUNTIF($O$3:O9,O9),"")) -> 3 | M9: =IF(COUNTA(E9:G9)=0,"",IF(B9<>"",B9,M8)) -> Arrangement 1 | N9: =IF(M9="","",IF(G9="","[control]",G9)) -> heat | O9: =IF(M9="","",M9&"|"&E9&"|"&IF(F9="","[blank]",F9)&"|"&N9) -> Arrangement 1|A|YPDA|heat | P9: =IF(M9="","",IF(E9="","Missing Set",IF(AND(B9<>"",COUNTIF($B$3:$B$92,B9)>1),"Duplicate Arrangement start",IF(D9="","Blank description","OK")))) -> OK
A10: =IF(M10="","",IFERROR(INDEX(Overview!$B$3:$B$62,MATCH(M10,Overview!$U$3:$U$62,0)),"")) -> 14.08.26 | C10: =IF(M10="","",COUNTIF($M$3:M10,M10)) -> 8 | D10: =IF(M10="","",IF(AND(F10="",G10=""),"",IF(F10<>"",F10,"")&IF(AND(F10<>"",G10<>"")," + ","")&IF(G10<>"",G10,"")&IF(H10<>"",", "&H10,""))) -> YPDA + heat, 4 | E10: A | F10: YPDA | G10: heat | H10: =IF(OR(M10="",E10=""),"",IF(COUNTIF($O$3:$O$92,O10)>1,COUNTIF($O$3:O10,O10),"")) -> 4 | M10: =IF(COUNTA(E10:G10)=0,"",IF(B10<>"",B10,M9)) -> Arrangement 1 | N10: =IF(M10="","",IF(G10="","[control]",G10)) -> heat | O10: =IF(M10="","",M10&"|"&E10&"|"&IF(F10="","[blank]",F10)&"|"&N10) -> Arrangement 1|A|YPDA|heat | P10: =IF(M10="","",IF(E10="","Missing Set",IF(AND(B10<>"",COUNTIF($B$3:$B$92,B10)>1),"Duplicate Arrangement start",IF(D10="","Blank description","OK")))) -> OK
A11: =IF(M11="","",IFERROR(INDEX(Overview!$B$3:$B$62,MATCH(M11,Overview!$U$3:$U$62,0)),"")) -> 14.08.26 | C11: =IF(M11="","",COUNTIF($M$3:M11,M11)) -> 9 | D11: =IF(M11="","",IF(AND(F11="",G11=""),"",IF(F11<>"",F11,"")&IF(AND(F11<>"",G11<>"")," + ","")&IF(G11<>"",G11,"")&IF(H11<>"",", "&H11,""))) -> YPDA + salt, 1 | E11: A | F11: YPDA | G11: salt | H11: =IF(OR(M11="",E11=""),"",IF(COUNTIF($O$3:$O$92,O11)>1,COUNTIF($O$3:O11,O11),"")) -> 1 | M11: =IF(COUNTA(E11:G11)=0,"",IF(B11<>"",B11,M10)) -> Arrangement 1 | N11: =IF(M11="","",IF(G11="","[control]",G11)) -> salt | O11: =IF(M11="","",M11&"|"&E11&"|"&IF(F11="","[blank]",F11)&"|"&N11) -> Arrangement 1|A|YPDA|salt | P11: =IF(M11="","",IF(E11="","Missing Set",IF(AND(B11<>"",COUNTIF($B$3:$B$92,B11)>1),"Duplicate Arrangement start",IF(D11="","Blank description","OK")))) -> OK
A12: =IF(M12="","",IFERROR(INDEX(Overview!$B$3:$B$62,MATCH(M12,Overview!$U$3:$U$62,0)),"")) -> 14.08.26 | C12: =IF(M12="","",COUNTIF($M$3:M12,M12)) -> 10 | D12: =IF(M12="","",IF(AND(F12="",G12=""),"",IF(F12<>"",F12,"")&IF(AND(F12<>"",G12<>"")," + ","")&IF(G12<>"",G12,"")&IF(H12<>"",", "&H12,""))) -> YPDA + salt, 2 | E12: A | F12: YPDA | G12: salt | H12: =IF(OR(M12="",E12=""),"",IF(COUNTIF($O$3:$O$92,O12)>1,COUNTIF($O$3:O12,O12),"")) -> 2 | M12: =IF(COUNTA(E12:G12)=0,"",IF(B12<>"",B12,M11)) -> Arrangement 1 | N12: =IF(M12="","",IF(G12="","[control]",G12)) -> salt | O12: =IF(M12="","",M12&"|"&E12&"|"&IF(F12="","[blank]",F12)&"|"&N12) -> Arrangement 1|A|YPDA|salt | P12: =IF(M12="","",IF(E12="","Missing Set",IF(AND(B12<>"",COUNTIF($B$3:$B$92,B12)>1),"Duplicate Arrangement start",IF(D12="","Blank description","OK")))) -> OK
A13: =IF(M13="","",IFERROR(INDEX(Overview!$B$3:$B$62,MATCH(M13,Overview!$U$3:$U$62,0)),"")) -> 14.08.26 | C13: =IF(M13="","",COUNTIF($M$3:M13,M13)) -> 11 | D13: =IF(M13="","",IF(AND(F13="",G13=""),"",IF(F13<>"",F13,"")&IF(AND(F13<>"",G13<>"")," + ","")&IF(G13<>"",G13,"")&IF(H13<>"",", "&H13,""))) -> YPDA + salt, 3 | E13: A | F13: YPDA | G13: salt | H13: =IF(OR(M13="",E13=""),"",IF(COUNTIF($O$3:$O$92,O13)>1,COUNTIF($O$3:O13,O13),"")) -> 3 | M13: =IF(COUNTA(E13:G13)=0,"",IF(B13<>"",B13,M12)) -> Arrangement 1 | N13: =IF(M13="","",IF(G13="","[control]",G13)) -> salt | O13: =IF(M13="","",M13&"|"&E13&"|"&IF(F13="","[blank]",F13)&"|"&N13) -> Arrangement 1|A|YPDA|salt | P13: =IF(M13="","",IF(E13="","Missing Set",IF(AND(B13<>"",COUNTIF($B$3:$B$92,B13)>1),"Duplicate Arrangement start",IF(D13="","Blank description","OK")))) -> OK
A14: =IF(M14="","",IFERROR(INDEX(Overview!$B$3:$B$62,MATCH(M14,Overview!$U$3:$U$62,0)),"")) -> 14.08.26 | C14: =IF(M14="","",COUNTIF($M$3:M14,M14)) -> 12 | D14: =IF(M14="","",IF(AND(F14="",G14=""),"",IF(F14<>"",F14,"")&IF(AND(F14<>"",G14<>"")," + ","")&IF(G14<>"",G14,"")&IF(H14<>"",", "&H14,""))) -> YPDA + salt, 4 | E14: A | F14: YPDA | G14: salt | H14: =IF(OR(M14="",E14=""),"",IF(COUNTIF($O$3:$O$92,O14)>1,COUNTIF($O$3:O14,O14),"")) -> 4 | M14: =IF(COUNTA(E14:G14)=0,"",IF(B14<>"",B14,M13)) -> Arrangement 1 | N14: =IF(M14="","",IF(G14="","[control]",G14)) -> salt | O14: =IF(M14="","",M14&"|"&E14&"|"&IF(F14="","[blank]",F14)&"|"&N14) -> Arrangement 1|A|YPDA|salt | P14: =IF(M14="","",IF(E14="","Missing Set",IF(AND(B14<>"",COUNTIF($B$3:$B$92,B14)>1),"Duplicate Arrangement start",IF(D14="","Blank description","OK")))) -> OK
A15: =IF(M15="","",IFERROR(INDEX(Overview!$B$3:$B$62,MATCH(M15,Overview!$U$3:$U$62,0)),"")) -> 14.08.26 | C15: =IF(M15="","",COUNTIF($M$3:M15,M15)) -> 13 | D15: =IF(M15="","",IF(AND(F15="",G15=""),"",IF(F15<>"",F15,"")&IF(AND(F15<>"",G15<>"")," + ","")&IF(G15<>"",G15,"")&IF(H15<>"",", "&H15,""))) -> YPDA, 1 | E15: B | F15: YPDA | H15: =IF(OR(M15="",E15=""),"",IF(COUNTIF($O$3:$O$92,O15)>1,COUNTIF($O$3:O15,O15),"")) -> 1 | M15: =IF(COUNTA(E15:G15)=0,"",IF(B15<>"",B15,M14)) -> Arrangement 1 | N15: =IF(M15="","",IF(G15="","[control]",G15)) -> [control] | O15: =IF(M15="","",M15&"|"&E15&"|"&IF(F15="","[blank]",F15)&"|"&N15) -> Arrangement 1|B|YPDA|[control] | P15: =IF(M15="","",IF(E15="","Missing Set",IF(AND(B15<>"",COUNTIF($B$3:$B$92,B15)>1),"Duplicate Arrangement start",IF(D15="","Blank description","OK")))) -> OK
A16: =IF(M16="","",IFERROR(INDEX(Overview!$B$3:$B$62,MATCH(M16,Overview!$U$3:$U$62,0)),"")) -> 14.08.26 | C16: =IF(M16="","",COUNTIF($M$3:M16,M16)) -> 14 | D16: =IF(M16="","",IF(AND(F16="",G16=""),"",IF(F16<>"",F16,"")&IF(AND(F16<>"",G16<>"")," + ","")&IF(G16<>"",G16,"")&IF(H16<>"",", "&H16,""))) -> YPDA, 2 | E16: B | F16: YPDA | H16: =IF(OR(M16="",E16=""),"",IF(COUNTIF($O$3:$O$92,O16)>1,COUNTIF($O$3:O16,O16),"")) -> 2 | M16: =IF(COUNTA(E16:G16)=0,"",IF(B16<>"",B16,M15)) -> Arrangement 1 | N16: =IF(M16="","",IF(G16="","[control]",G16)) -> [control] | O16: =IF(M16="","",M16&"|"&E16&"|"&IF(F16="","[blank]",F16)&"|"&N16) -> Arrangement 1|B|YPDA|[control] | P16: =IF(M16="","",IF(E16="","Missing Set",IF(AND(B16<>"",COUNTIF($B$3:$B$92,B16)>1),"Duplicate Arrangement start",IF(D16="","Blank description","OK")))) -> OK
A17: =IF(M17="","",IFERROR(INDEX(Overview!$B$3:$B$62,MATCH(M17,Overview!$U$3:$U$62,0)),"")) -> 14.08.26 | C17: =IF(M17="","",COUNTIF($M$3:M17,M17)) -> 15 | D17: =IF(M17="","",IF(AND(F17="",G17=""),"",IF(F17<>"",F17,"")&IF(AND(F17<>"",G17<>"")," + ","")&IF(G17<>"",G17,"")&IF(H17<>"",", "&H17,""))) -> YPDA, 3 | E17: B | F17: YPDA | H17: =IF(OR(M17="",E17=""),"",IF(COUNTIF($O$3:$O$92,O17)>1,COUNTIF($O$3:O17,O17),"")) -> 3 | M17: =IF(COUNTA(E17:G17)=0,"",IF(B17<>"",B17,M16)) -> Arrangement 1 | N17: =IF(M17="","",IF(G17="","[control]",G17)) -> [control] | O17: =IF(M17="","",M17&"|"&E17&"|"&IF(F17="","[blank]",F17)&"|"&N17) -> Arrangement 1|B|YPDA|[control] | P17: =IF(M17="","",IF(E17="","Missing Set",IF(AND(B17<>"",COUNTIF($B$3:$B$92,B17)>1),"Duplicate Arrangement start",IF(D17="","Blank description","OK")))) -> OK
A18: =IF(M18="","",IFERROR(INDEX(Overview!$B$3:$B$62,MATCH(M18,Overview!$U$3:$U$62,0)),"")) -> 14.08.26 | C18: =IF(M18="","",COUNTIF($M$3:M18,M18)) -> 16 | D18: =IF(M18="","",IF(AND(F18="",G18=""),"",IF(F18<>"",F18,"")&IF(AND(F18<>"",G18<>"")," + ","")&IF(G18<>"",G18,"")&IF(H18<>"",", "&H18,""))) -> YPDA, 4 | E18: B | F18: YPDA | H18: =IF(OR(M18="",E18=""),"",IF(COUNTIF($O$3:$O$92,O18)>1,COUNTIF($O$3:O18,O18),"")) -> 4 | M18: =IF(COUNTA(E18:G18)=0,"",IF(B18<>"",B18,M17)) -> Arrangement 1 | N18: =IF(M18="","",IF(G18="","[control]",G18)) -> [control] | O18: =IF(M18="","",M18&"|"&E18&"|"&IF(F18="","[blank]",F18)&"|"&N18) -> Arrangement 1|B|YPDA|[control] | P18: =IF(M18="","",IF(E18="","Missing Set",IF(AND(B18<>"",COUNTIF($B$3:$B$92,B18)>1),"Duplicate Arrangement start",IF(D18="","Blank description","OK")))) -> OK
A19: =IF(M19="","",IFERROR(INDEX(Overview!$B$3:$B$62,MATCH(M19,Overview!$U$3:$U$62,0)),"")) -> 14.08.26 | C19: =IF(M19="","",COUNTIF($M$3:M19,M19)) -> 17 | D19: =IF(M19="","",IF(AND(F19="",G19=""),"",IF(F19<>"",F19,"")&IF(AND(F19<>"",G19<>"")," + ","")&IF(G19<>"",G19,"")&IF(H19<>"",", "&H19,""))) -> YPDA + heat, 1 | E19: B | F19: YPDA | G19: heat | H19: =IF(OR(M19="",E19=""),"",IF(COUNTIF($O$3:$O$92,O19)>1,COUNTIF($O$3:O19,O19),"")) -> 1 | M19: =IF(COUNTA(E19:G19)=0,"",IF(B19<>"",B19,M18)) -> Arrangement 1 | N19: =IF(M19="","",IF(G19="","[control]",G19)) -> heat | O19: =IF(M19="","",M19&"|"&E19&"|"&IF(F19="","[blank]",F19)&"|"&N19) -> Arrangement 1|B|YPDA|heat | P19: =IF(M19="","",IF(E19="","Missing Set",IF(AND(B19<>"",COUNTIF($B$3:$B$92,B19)>1),"Duplicate Arrangement start",IF(D19="","Blank description","OK")))) -> OK
A20: =IF(M20="","",IFERROR(INDEX(Overview!$B$3:$B$62,MATCH(M20,Overview!$U$3:$U$62,0)),"")) -> 14.08.26 | C20: =IF(M20="","",COUNTIF($M$3:M20,M20)) -> 18 | D20: =IF(M20="","",IF(AND(F20="",G20=""),"",IF(F20<>"",F20,"")&IF(AND(F20<>"",G20<>"")," + ","")&IF(G20<>"",G20,"")&IF(H20<>"",", "&H20,""))) -> YPDA + heat, 2 | E20: B | F20: YPDA | G20: heat | H20: =IF(OR(M20="",E20=""),"",IF(COUNTIF($O$3:$O$92,O20)>1,COUNTIF($O$3:O20,O20),"")) -> 2 | M20: =IF(COUNTA(E20:G20)=0,"",IF(B20<>"",B20,M19)) -> Arrangement 1 | N20: =IF(M20="","",IF(G20="","[control]",G20)) -> heat | O20: =IF(M20="","",M20&"|"&E20&"|"&IF(F20="","[blank]",F20)&"|"&N20) -> Arrangement 1|B|YPDA|heat | P20: =IF(M20="","",IF(E20="","Missing Set",IF(AND(B20<>"",COUNTIF($B$3:$B$92,B20)>1),"Duplicate Arrangement start",IF(D20="","Blank description","OK")))) -> OK
A21: =IF(M21="","",IFERROR(INDEX(Overview!$B$3:$B$62,MATCH(M21,Overview!$U$3:$U$62,0)),"")) -> 14.08.26 | C21: =IF(M21="","",COUNTIF($M$3:M21,M21)) -> 19 | D21: =IF(M21="","",IF(AND(F21="",G21=""),"",IF(F21<>"",F21,"")&IF(AND(F21<>"",G21<>"")," + ","")&IF(G21<>"",G21,"")&IF(H21<>"",", "&H21,""))) -> YPDA + heat, 3 | E21: B | F21: YPDA | G21: heat | H21: =IF(OR(M21="",E21=""),"",IF(COUNTIF($O$3:$O$92,O21)>1,COUNTIF($O$3:O21,O21),"")) -> 3 | M21: =IF(COUNTA(E21:G21)=0,"",IF(B21<>"",B21,M20)) -> Arrangement 1 | N21: =IF(M21="","",IF(G21="","[control]",G21)) -> heat | O21: =IF(M21="","",M21&"|"&E21&"|"&IF(F21="","[blank]",F21)&"|"&N21) -> Arrangement 1|B|YPDA|heat | P21: =IF(M21="","",IF(E21="","Missing Set",IF(AND(B21<>"",COUNTIF($B$3:$B$92,B21)>1),"Duplicate Arrangement start",IF(D21="","Blank description","OK")))) -> OK
A22: =IF(M22="","",IFERROR(INDEX(Overview!$B$3:$B$62,MATCH(M22,Overview!$U$3:$U$62,0)),"")) -> 14.08.26 | C22: =IF(M22="","",COUNTIF($M$3:M22,M22)) -> 20 | D22: =IF(M22="","",IF(AND(F22="",G22=""),"",IF(F22<>"",F22,"")&IF(AND(F22<>"",G22<>"")," + ","")&IF(G22<>"",G22,"")&IF(H22<>"",", "&H22,""))) -> YPDA + heat, 4 | E22: B | F22: YPDA | G22: heat | H22: =IF(OR(M22="",E22=""),"",IF(COUNTIF($O$3:$O$92,O22)>1,COUNTIF($O$3:O22,O22),"")) -> 4 | M22: =IF(COUNTA(E22:G22)=0,"",IF(B22<>"",B22,M21)) -> Arrangement 1 | N22: =IF(M22="","",IF(G22="","[control]",G22)) -> heat | O22: =IF(M22="","",M22&"|"&E22&"|"&IF(F22="","[blank]",F22)&"|"&N22) -> Arrangement 1|B|YPDA|heat | P22: =IF(M22="","",IF(E22="","Missing Set",IF(AND(B22<>"",COUNTIF($B$3:$B$92,B22)>1),"Duplicate Arrangement start",IF(D22="","Blank description","OK")))) -> OK
A23: =IF(M23="","",IFERROR(INDEX(Overview!$B$3:$B$62,MATCH(M23,Overview!$U$3:$U$62,0)),"")) -> 14.08.26 | C23: =IF(M23="","",COUNTIF($M$3:M23,M23)) -> 21 | D23: =IF(M23="","",IF(AND(F23="",G23=""),"",IF(F23<>"",F23,"")&IF(AND(F23<>"",G23<>"")," + ","")&IF(G23<>"",G23,"")&IF(H23<>"",", "&H23,""))) -> YPDA + salt, 1 | E23: B | F23: YPDA | G23: salt | H23: =IF(OR(M23="",E23=""),"",IF(COUNTIF($O$3:$O$92,O23)>1,COUNTIF($O$3:O23,O23),"")) -> 1 | M23: =IF(COUNTA(E23:G23)=0,"",IF(B23<>"",B23,M22)) -> Arrangement 1 | N23: =IF(M23="","",IF(G23="","[control]",G23)) -> salt | O23: =IF(M23="","",M23&"|"&E23&"|"&IF(F23="","[blank]",F23)&"|"&N23) -> Arrangement 1|B|YPDA|salt | P23: =IF(M23="","",IF(E23="","Missing Set",IF(AND(B23<>"",COUNTIF($B$3:$B$92,B23)>1),"Duplicate Arrangement start",IF(D23="","Blank description","OK")))) -> OK
A24: =IF(M24="","",IFERROR(INDEX(Overview!$B$3:$B$62,MATCH(M24,Overview!$U$3:$U$62,0)),"")) -> 14.08.26 | C24: =IF(M24="","",COUNTIF($M$3:M24,M24)) -> 22 | D24: =IF(M24="","",IF(AND(F24="",G24=""),"",IF(F24<>"",F24,"")&IF(AND(F24<>"",G24<>"")," + ","")&IF(G24<>"",G24,"")&IF(H24<>"",", "&H24,""))) -> YPDA + salt, 2 | E24: B | F24: YPDA | G24: salt | H24: =IF(OR(M24="",E24=""),"",IF(COUNTIF($O$3:$O$92,O24)>1,COUNTIF($O$3:O24,O24),"")) -> 2 | M24: =IF(COUNTA(E24:G24)=0,"",IF(B24<>"",B24,M23)) -> Arrangement 1 | N24: =IF(M24="","",IF(G24="","[control]",G24)) -> salt | O24: =IF(M24="","",M24&"|"&E24&"|"&IF(F24="","[blank]",F24)&"|"&N24) -> Arrangement 1|B|YPDA|salt | P24: =IF(M24="","",IF(E24="","Missing Set",IF(AND(B24<>"",COUNTIF($B$3:$B$92,B24)>1),"Duplicate Arrangement start",IF(D24="","Blank description","OK")))) -> OK
A25: =IF(M25="","",IFERROR(INDEX(Overview!$B$3:$B$62,MATCH(M25,Overview!$U$3:$U$62,0)),"")) -> 14.08.26 | C25: =IF(M25="","",COUNTIF($M$3:M25,M25)) -> 23 | D25: =IF(M25="","",IF(AND(F25="",G25=""),"",IF(F25<>"",F25,"")&IF(AND(F25<>"",G25<>"")," + ","")&IF(G25<>"",G25,"")&IF(H25<>"",", "&H25,""))) -> YPDA + salt, 3 | E25: B | F25: YPDA | G25: salt | H25: =IF(OR(M25="",E25=""),"",IF(COUNTIF($O$3:$O$92,O25)>1,COUNTIF($O$3:O25,O25),"")) -> 3 | M25: =IF(COUNTA(E25:G25)=0,"",IF(B25<>"",B25,M24)) -> Arrangement 1 | N25: =IF(M25="","",IF(G25="","[control]",G25)) -> salt | O25: =IF(M25="","",M25&"|"&E25&"|"&IF(F25="","[blank]",F25)&"|"&N25) -> Arrangement 1|B|YPDA|salt | P25: =IF(M25="","",IF(E25="","Missing Set",IF(AND(B25<>"",COUNTIF($B$3:$B$92,B25)>1),"Duplicate Arrangement start",IF(D25="","Blank description","OK")))) -> OK
A26: =IF(M26="","",IFERROR(INDEX(Overview!$B$3:$B$62,MATCH(M26,Overview!$U$3:$U$62,0)),"")) -> 14.08.26 | C26: =IF(M26="","",COUNTIF($M$3:M26,M26)) -> 24 | D26: =IF(M26="","",IF(AND(F26="",G26=""),"",IF(F26<>"",F26,"")&IF(AND(F26<>"",G26<>"")," + ","")&IF(G26<>"",G26,"")&IF(H26<>"",", "&H26,""))) -> YPDA + salt, 4 | E26: B | F26: YPDA | G26: salt | H26: =IF(OR(M26="",E26=""),"",IF(COUNTIF($O$3:$O$92,O26)>1,COUNTIF($O$3:O26,O26),"")) -> 4 | M26: =IF(COUNTA(E26:G26)=0,"",IF(B26<>"",B26,M25)) -> Arrangement 1 | N26: =IF(M26="","",IF(G26="","[control]",G26)) -> salt | O26: =IF(M26="","",M26&"|"&E26&"|"&IF(F26="","[blank]",F26)&"|"&N26) -> Arrangement 1|B|YPDA|salt | P26: =IF(M26="","",IF(E26="","Missing Set",IF(AND(B26<>"",COUNTIF($B$3:$B$92,B26)>1),"Duplicate Arrangement start",IF(D26="","Blank description","OK")))) -> OK
A27: =IF(M27="","",IFERROR(INDEX(Overview!$B$3:$B$62,MATCH(M27,Overview!$U$3:$U$62,0)),"")) -> 16.08.26 | B27: Arrangement 2 | C27: =IF(M27="","",COUNTIF($M$3:M27,M27)) -> 1 | D27: =IF(M27="","",IF(AND(F27="",G27=""),"",IF(F27<>"",F27,"")&IF(AND(F27<>"",G27<>"")," + ","")&IF(G27<>"",G27,"")&IF(H27<>"",", "&H27,""))) -> YPDA, 1 | E27: A | F27: YPDA | H27: =IF(OR(M27="",E27=""),"",IF(COUNTIF($O$3:$O$92,O27)>1,COUNTIF($O$3:O27,O27),"")) -> 1 | M27: =IF(COUNTA(E27:G27)=0,"",IF(B27<>"",B27,M26)) -> Arrangement 2 | N27: =IF(M27="","",IF(G27="","[control]",G27)) -> [control] | O27: =IF(M27="","",M27&"|"&E27&"|"&IF(F27="","[blank]",F27)&"|"&N27) -> Arrangement 2|A|YPDA|[control] | P27: =IF(M27="","",IF(E27="","Missing Set",IF(AND(B27<>"",COUNTIF($B$3:$B$92,B27)>1),"Duplicate Arrangement start",IF(D27="","Blank description","OK")))) -> OK
A28: =IF(M28="","",IFERROR(INDEX(Overview!$B$3:$B$62,MATCH(M28,Overview!$U$3:$U$62,0)),"")) -> 16.08.26 | C28: =IF(M28="","",COUNTIF($M$3:M28,M28)) -> 2 | D28: =IF(M28="","",IF(AND(F28="",G28=""),"",IF(F28<>"",F28,"")&IF(AND(F28<>"",G28<>"")," + ","")&IF(G28<>"",G28,"")&IF(H28<>"",", "&H28,""))) -> YPDA, 2 | E28: A | F28: YPDA | H28: =IF(OR(M28="",E28=""),"",IF(COUNTIF($O$3:$O$92,O28)>1,COUNTIF($O$3:O28,O28),"")) -> 2 | M28: =IF(COUNTA(E28:G28)=0,"",IF(B28<>"",B28,M27)) -> Arrangement 2 | N28: =IF(M28="","",IF(G28="","[control]",G28)) -> [control] | O28: =IF(M28="","",M28&"|"&E28&"|"&IF(F28="","[blank]",F28)&"|"&N28) -> Arrangement 2|A|YPDA|[control] | P28: =IF(M28="","",IF(E28="","Missing Set",IF(AND(B28<>"",COUNTIF($B$3:$B$92,B28)>1),"Duplicate Arrangement start",IF(D28="","Blank description","OK")))) -> OK
